Workbook

Sheet 📊 Tổng Quan & Tiến Độ
A1: 🚀 BẢNG THEO DÕI THỬ THÁCH XÂY KÊNH (08/09 - 26/10/2026)
A3: 📌 Bắt đầu: 08/09/2026 - Kết thúc: 26/10/2026 (49 Ngày) | Nhiệm vụ: 1 Reel FB + 2 Bài viết FB + 1 Bài tập nhóm (Kèm Link & Ảnh)
A5: 🏆 BẢNG TỔNG KẾT TIẾN ĐỘ 9 THÀNH VIÊN
A6: STT | B6: Họ và Tên | C6: Mục tiêu Reel | D6: Reel Đã Nộp | E6: Mục tiêu Bài FB | F6: Bài FB Đã Nộp | G6: Mục tiêu Bài tập | H6: Bài tập Đã Nộp | I6: Tổng Mục Tiêu | J6: Tổng Hoàn Thành | K6: Tỷ Lệ Hoàn Thành | L6: Đánh Giá Tiến Độ
A7: 1 | B7: Nancy | C7: 49 | D7: =COUNTIFS('📋 Báo Cáo 49 Ngày'!$F$5:$F$445, B7, '📋 Báo Cáo 49 Ngày'!$G$5:$G$445, "<>") | E7: 98 | F7: =COUNTIFS('📋 Báo Cáo 49 Ngày'!$F$5:$F$445, B7, '📋 Báo Cáo 49 Ngày'!$I$5:$I$445, "<>") + COUNTIFS('📋 Báo Cáo 49 Ngày'!$F$5:$F$445, B7, '📋 Báo Cáo 49 Ngày'!$K$5:$K$445, "<>") | G7: 49 | H7: =COUNTIFS('📋 Báo Cáo 49 Ngày'!$F$5:$F$445, B7, '📋 Báo Cáo 49 Ngày'!$M$5:$M$445, "<>") | I7: =C7+E7+G7 | J7: =D7+F7+H7 | K7: =IF(I7>0, J7/I7, 0) | L7: =IF(K7>=1, "⭐ Xuất sắc (100%)", IF(K7>=0.8, "🔥 Rất Tốt (>=80%)", IF(K7>=0.5, "⚡ Đang Tiến Bộ", "⚠️ Cần Tăng Tốc")))
A8: 2 | B8: Hoài Học Mãi | C8: 49 | D8: =COUNTIFS('📋 Báo Cáo 49 Ngày'!$F$5:$F$445, B8, '📋 Báo Cáo 49 Ngày'!$G$5:$G$445, "<>") | E8: 98 | F8: =COUNTIFS('📋 Báo Cáo 49 Ngày'!$F$5:$F$445, B8, '📋 Báo Cáo 49 Ngày'!$I$5:$I$445, "<>") + COUNTIFS('📋 Báo Cáo 49 Ngày'!$F$5:$F$445, B8, '📋 Báo Cáo 49 Ngày'!$K$5:$K$445, "<>") | G8: 49 | H8: =COUNTIFS('📋 Báo Cáo 49 Ngày'!$F$5:$F$445, B8, '📋 Báo Cáo 49 Ngày'!$M$5:$M$445, "<>") | I8: =C8+E8+G8 | J8: =D8+F8+H8 | K8: =IF(I8>0, J8/I8, 0) | L8: =IF(K8>=1, "⭐ Xuất sắc (100%)", IF(K8>=0.8, "🔥 Rất Tốt (>=80%)", IF(K8>=0.5, "⚡ Đang Tiến Bộ", "⚠️ Cần Tăng Tốc")))
A9: 3 | B9: Lambee | C9: 49 | D9: =COUNTIFS('📋 Báo Cáo 49 Ngày'!$F$5:$F$445, B9, '📋 Báo Cáo 49 Ngày'!$G$5:$G$445, "<>") | E9: 98 | F9: =COUNTIFS('📋 Báo Cáo 49 Ngày'!$F$5:$F$445, B9, '📋 Báo Cáo 49 Ngày'!$I$5:$I$445, "<>") + COUNTIFS('📋 Báo Cáo 49 Ngày'!$F$5:$F$445, B9, '📋 Báo Cáo 49 Ngày'!$K$5:$K$445, "<>") | G9: 49 | H9: =COUNTIFS('📋 Báo Cáo 49 Ngày'!$F$5:$F$445, B9, '📋 Báo Cáo 49 Ngày'!$M$5:$M$445, "<>") | I9: =C9+E9+G9 | J9: =D9+F9+H9 | K9: =IF(I9>0, J9/I9, 0) | L9: =IF(K9>=1, "⭐ Xuất sắc (100%)", IF(K9>=0.8, "🔥 Rất Tốt (>=80%)", IF(K9>=0.5, "⚡ Đang Tiến Bộ", "⚠️ Cần Tăng Tốc")))
A10: 4 | B10: Nhung Hoàng | C10: 49 | D10: =COUNTIFS('📋 Báo Cáo 49 Ngày'!$F$5:$F$445, B10, '📋 Báo Cáo 49 Ngày'!$G$5:$G$445, "<>") | E10: 98 | F10: =COUNTIFS('📋 Báo Cáo 49 Ngày'!$F$5:$F$445, B10, '📋 Báo Cáo 49 Ngày'!$I$5:$I$445, "<>") + COUNTIFS('📋 Báo Cáo 49 Ngày'!$F$5:$F$445, B10, '📋 Báo Cáo 49 Ngày'!$K$5:$K$445, "<>") | G10: 49 | H10: =COUNTIFS('📋 Báo Cáo 49 Ngày'!$F$5:$F$445, B10, '📋 Báo Cáo 49 Ngày'!$M$5:$M$445, "<>") | I10: =C10+E10+G10 | J10: =D10+F10+H10 | K10: =IF(I10>0, J10/I10, 0) | L10: =IF(K10>=1, "⭐ Xuất sắc (100%)", IF(K10>=0.8, "🔥 Rất Tốt (>=80%)", IF(K10>=0.5, "⚡ Đang Tiến Bộ", "⚠️ Cần Tăng Tốc")))
A11: 5 | B11: Quỳnh Thu | C11: 49 | D11: =COUNTIFS('📋 Báo Cáo 49 Ngày'!$F$5:$F$445, B11, '📋 Báo Cáo 49 Ngày'!$G$5:$G$445, "<>") | E11: 98 | F11: =COUNTIFS('📋 Báo Cáo 49 Ngày'!$F$5:$F$445, B11, '📋 Báo Cáo 49 Ngày'!$I$5:$I$445, "<>") + COUNTIFS('📋 Báo Cáo 49 Ngày'!$F$5:$F$445, B11, '📋 Báo Cáo 49 Ngày'!$K$5:$K$445, "<>") | G11: 49 | H11: =COUNTIFS('📋 Báo Cáo 49 Ngày'!$F$5:$F$445, B11, '📋 Báo Cáo 49 Ngày'!$M$5:$M$445, "<>") | I11: =C11+E11+G11 | J11: =D11+F11+H11 | K11: =IF(I11>0, J11/I11, 0) | L11: =IF(K11>=1, "⭐ Xuất sắc (100%)", IF(K11>=0.8, "🔥 Rất Tốt (>=80%)", IF(K11>=0.5, "⚡ Đang Tiến Bộ", "⚠️ Cần Tăng Tốc")))
A12: 6 | B12: TanAnh Pham | C12: 49 | D12: =COUNTIFS('📋 Báo Cáo 49 Ngày'!$F$5:$F$445, B12, '📋 Báo Cáo 49 Ngày'!$G$5:$G$445, "<>") | E12: 98 | F12: =COUNTIFS('📋 Báo Cáo 49 Ngày'!$F$5:$F$445, B12, '📋 Báo Cáo 49 Ngày'!$I$5:$I$445, "<>") + COUNTIFS('📋 Báo Cáo 49 Ngày'!$F$5:$F$445, B12, '📋 Báo Cáo 49 Ngày'!$K$5:$K$445, "<>") | G12: 49 | H12: =COUNTIFS('📋 Báo Cáo 49 Ngày'!$F$5:$F$445, B12, '📋 Báo Cáo 49 Ngày'!$M$5:$M$445, "<>") | I12: =C12+E12+G12 | J12: =D12+F12+H12 | K12: =IF(I12>0, J12/I12, 0) | L12: =IF(K12>=1, "⭐ Xuất sắc (100%)", IF(K12>=0.8, "🔥 Rất Tốt (>=80%)", IF(K12>=0.5, "⚡ Đang Tiến Bộ", "⚠️ Cần Tăng Tốc")))
A13: 7 | B13: Thảo Collins Edu | C13: 49 | D13: =COUNTIFS('📋 Báo Cáo 49 Ngày'!$F$5:$F$445, B13, '📋 Báo Cáo 49 Ngày'!$G$5:$G$445, "<>") | E13: 98 | F13: =COUNTIFS('📋 Báo Cáo 49 Ngày'!$F$5:$F$445, B13, '📋 Báo Cáo 49 Ngày'!$I$5:$I$445, "<>") + COUNTIFS('📋 Báo Cáo 49 Ngày'!$F$5:$F$445, B13, '📋 Báo Cáo 49 Ngày'!$K$5:$K$445, "<>") | G13: 49 | H13: =COUNTIFS('📋 Báo Cáo 49 Ngày'!$F$5:$F$445, B13, '📋 Báo Cáo 49 Ngày'!$M$5:$M$445, "<>") | I13: =C13+E13+G13 | J13: =D13+F13+H13 | K13: =IF(I13>0, J13/I13, 0) | L13: =IF(K13>=1, "⭐ Xuất sắc (100%)", IF(K13>=0.8, "🔥 Rất Tốt (>=80%)", IF(K13>=0.5, "⚡ Đang Tiến Bộ", "⚠️ Cần Tăng Tốc")))
A14: 8 | B14: Trần Quế Lam | C14: 49 | D14: =COUNTIFS('📋 Báo Cáo 49 Ngày'!$F$5:$F$445, B14, '📋 Báo Cáo 49 Ngày'!$G$5:$G$445, "<>") | E14: 98 | F14: =COUNTIFS('📋 Báo Cáo 49 Ngày'!$F$5:$F$445, B14, '📋 Báo Cáo 49 Ngày'!$I$5:$I$445, "<>") + COUNTIFS('📋 Báo Cáo 49 Ngày'!$F$5:$F$445, B14, '📋 Báo Cáo 49 Ngày'!$K$5:$K$445, "<>") | G14: 49 | H14: =COUNTIFS('📋 Báo Cáo 49 Ngày'!$F$5:$F$445, B14, '📋 Báo Cáo 49 Ngày'!$M$5:$M$445, "<>") | I14: =C14+E14+G14 | J14: =D14+F14+H14 | K14: =IF(I14>0, J14/I14, 0) | L14: =IF(K14>=1, "⭐ Xuất sắc (100%)", IF(K14>=0.8, "🔥 Rất Tốt (>=80%)", IF(K14>=0.5, "⚡ Đang Tiến Bộ", "⚠️ Cần Tăng Tốc")))
A15: 9 | B15: Phạm Huyền | C15: 49 | D15: =COUNTIFS('📋 Báo Cáo 49 Ngày'!$F$5:$F$445, B15, '📋 Báo Cáo 49 Ngày'!$G$5:$G$445, "<>") | E15: 98 | F15: =COUNTIFS('📋 Báo Cáo 49 Ngày'!$F$5:$F$445, B15, '📋 Báo Cáo 49 Ngày'!$I$5:$I$445, "<>") + COUNTIFS('📋 Báo Cáo 49 Ngày'!$F$5:$F$445, B15, '📋 Báo Cáo 49 Ngày'!$K$5:$K$445, "<>") | G15: 49 | H15: =COUNTIFS('📋 Báo Cáo 49 Ngày'!$F$5:$F$445, B15, '📋 Báo Cáo 49 Ngày'!$M$5:$M$445, "<>") | I15: =C15+E15+G15 | J15: =D15+F15+H15 | K15: =IF(I15>0, J15/I15, 0) | L15: =IF(K15>=1, "⭐ Xuất sắc (100%)", IF(K15>=0.8, "🔥 Rất Tốt (>=80%)", IF(K15>=0.5, "⚡ Đang Tiến Bộ", "⚠️ Cần Tăng Tốc")))
A16: TỔNG CỘNG TOÀN NHÓM | C16: =SUM(C7:C15) | D16: =SUM(D7:D15) | E16: =SUM(E7:E15) | F16: =SUM(F7:F15) | G16: =SUM(G7:G15) | H16: =SUM(H7:H15) | I16: =SUM(I7:I15) | J16: =SUM(J7:J15) | K16: =IF(I16>0, J16/I16, 0) | L16: =IF(K16>=0.8, "🎉 Toàn nhóm đạt chỉ tiêu", "💪 Cùng nhau cố gắng")
A19: 📅 BẢNG TIẾN ĐỘ THEO TỪNG TUẦN (08/09 -> 26/10/2026)
A20: Tuần | B20: Khoảng Thời Gian | C20: Tổng NV Cả Nhóm | D20: Reel Đã Nộp | E20: Bài FB Đã Nộp | F20: Bài Tập Đã Nộp | G20: Tổng Đã Nộp | H20: Tỷ Lệ Đạt (%) | I20: Tình Trạng Tuần
A21: Tuần 1 | B21: 08/09 - 14/09/2026 | C21: 252 | D21: =COUNTIFS('📋 Báo Cáo 49 Ngày'!$B$5:$B$445, "Tuần " & 1, '📋 Báo Cáo 49 Ngày'!$G$5:$G$445, "<>") | E21: =COUNTIFS('📋 Báo Cáo 49 Ngày'!$B$5:$B$445, "Tuần " & 1, '📋 Báo Cáo 49 Ngày'!$I$5:$I$445, "<>") + COUNTIFS('📋 Báo Cáo 49 Ngày'!$B$5:$B$445, "Tuần " & 1, '📋 Báo Cáo 49 Ngày'!$K$5:$K$445, "<>") | F21: =COUNTIFS('📋 Báo Cáo 49 Ngày'!$B$5:$B$445, "Tuần " & 1, '📋 Báo Cáo 49 Ngày'!$M$5:$M$445, "<>") | G21: =D21+E21+F21 | H21: =IF(C21>0, G21/C21, 0) | I21: =IF(H21>=0.9, "✅ Về đích xuất sắc", IF(H21>=0.7, "⚡ Tiến độ ổn định", IF(H21>0, "⏳ Đang thực hiện", "⚪ Chưa bắt đầu")))
A22: Tuần 2 | B22: 15/09 - 21/09/2026 | C22: 252 | D22: =COUNTIFS('📋 Báo Cáo 49 Ngày'!$B$5:$B$445, "Tuần " & 2, '📋 Báo Cáo 49 Ngày'!$G$5:$G$445, "<>") | E22: =COUNTIFS('📋 Báo Cáo 49 Ngày'!$B$5:$B$445, "Tuần " & 2, '📋 Báo Cáo 49 Ngày'!$I$5:$I$445, "<>") + COUNTIFS('📋 Báo Cáo 49 Ngày'!$B$5:$B$445, "Tuần " & 2, '📋 Báo Cáo 49 Ngày'!$K$5:$K$445, "<>") | F22: =COUNTIFS('📋 Báo Cáo 49 Ngày'!$B$5:$B$445, "Tuần " & 2, '📋 Báo Cáo 49 Ngày'!$M$5:$M$445, "<>") | G22: =D22+E22+F22 | H22: =IF(C22>0, G22/C22, 0) | I22: =IF(H22>=0.9, "✅ Về đích xuất sắc", IF(H22>=0.7, "⚡ Tiến độ ổn định", IF(H22>0, "⏳ Đang thực hiện", "⚪ Chưa bắt đầu")))
A23: Tuần 3 | B23: 22/09 - 28/09/2026 | C23: 252 | D23: =COUNTIFS('📋 Báo Cáo 49 Ngày'!$B$5:$B$445, "Tuần " & 3, '📋 Báo Cáo 49 Ngày'!$G$5:$G$445, "<>") | E23: =COUNTIFS('📋 Báo Cáo 49 Ngày'!$B$5:$B$445, "Tuần " & 3, '📋 Báo Cáo 49 Ngày'!$I$5:$I$445, "<>") + COUNTIFS('📋 Báo Cáo 49 Ngày'!$B$5:$B$445, "Tuần " & 3, '📋 Báo Cáo 49 Ngày'!$K$5:$K$445, "<>") | F23: =COUNTIFS('📋 Báo Cáo 49 Ngày'!$B$5:$B$445, "Tuần " & 3, '📋 Báo Cáo 49 Ngày'!$M$5:$M$445, "<>") | G23: =D23+E23+F23 | H23: =IF(C23>0, G23/C23, 0) | I23: =IF(H23>=0.9, "✅ Về đích xuất sắc", IF(H23>=0.7, "⚡ Tiến độ ổn định", IF(H23>0, "⏳ Đang thực hiện", "⚪ Chưa bắt đầu")))
A24: Tuần 4 | B24: 29/09 - 05/10/2026 | C24: 252 | D24: =COUNTIFS('📋 Báo Cáo 49 Ngày'!$B$5:$B$445, "Tuần " & 4, '📋 Báo Cáo 49 Ngày'!$G$5:$G$445, "<>") | E24: =COUNTIFS('📋 Báo Cáo 49 Ngày'!$B$5:$B$445, "Tuần " & 4, '📋 Báo Cáo 49 Ngày'!$I$5:$I$445, "<>") + COUNTIFS('📋 Báo Cáo 49 Ngày'!$B$5:$B$445, "Tuần " & 4, '📋 Báo Cáo 49 Ngày'!$K$5:$K$445, "<>") | F24: =COUNTIFS('📋 Báo Cáo 49 Ngày'!$B$5:$B$445, "Tuần " & 4, '📋 Báo Cáo 49 Ngày'!$M$5:$M$445, "<>") | G24: =D24+E24+F24 | H24: =IF(C24>0, G24/C24, 0) | I24: =IF(H24>=0.9, "✅ Về đích xuất sắc", IF(H24>=0.7, "⚡ Tiến độ ổn định", IF(H24>0, "⏳ Đang thực hiện", "⚪ Chưa bắt đầu")))
A25: Tuần 5 | B25: 06/10 - 12/10/2026 | C25: 252 | D25: =COUNTIFS('📋 Báo Cáo 49 Ngày'!$B$5:$B$445, "Tuần " & 5, '📋 Báo Cáo 49 Ngày'!$G$5:$G$445, "<>") | E25: =COUNTIFS('📋 Báo Cáo 49 Ngày'!$B$5:$B$445, "Tuần " & 5, '📋 Báo Cáo 49 Ngày'!$I$5:$I$445, "<>") + COUNTIFS('📋 Báo Cáo 49 Ngày'!$B$5:$B$445, "Tuần " & 5, '📋 Báo Cáo 49 Ngày'!$K$5:$K$445, "<>") | F25: =COUNTIFS('📋 Báo Cáo 49 Ngày'!$B$5:$B$445, "Tuần " & 5, '📋 Báo Cáo 49 Ngày'!$M$5:$M$445, "<>") | G25: =D25+E25+F25 | H25: =IF(C25>0, G25/C25, 0) | I25: =IF(H25>=0.9, "✅ Về đích xuất sắc", IF(H25>=0.7, "⚡ Tiến độ ổn định", IF(H25>0, "⏳ Đang thực hiện", "⚪ Chưa bắt đầu")))
A26: Tuần 6 | B26: 13/10 - 19/10/2026 | C26: 252 | D26: =COUNTIFS('📋 Báo Cáo 49 Ngày'!$B$5:$B$445, "Tuần " & 6, '📋 Báo Cáo 49 Ngày'!$G$5:$G$445, "<>") | E26: =COUNTIFS('📋 Báo Cáo 49 Ngày'!$B$5:$B$445, "Tuần " & 6, '📋 Báo Cáo 49 Ngày'!$I$5:$I$445, "<>") + COUNTIFS('📋 Báo Cáo 49 Ngày'!$B$5:$B$445, "Tuần " & 6, '📋 Báo Cáo 49 Ngày'!$K$5:$K$445, "<>") | F26: =COUNTIFS('📋 Báo Cáo 49 Ngày'!$B$5:$B$445, "Tuần " & 6, '📋 Báo Cáo 49 Ngày'!$M$5:$M$445, "<>") | G26: =D26+E26+F26 | H26: =IF(C26>0, G26/C26, 0) | I26: =IF(H26>=0.9, "✅ Về đích xuất sắc", IF(H26>=0.7, "⚡ Tiến độ ổn định", IF(H26>0, "⏳ Đang thực hiện", "⚪ Chưa bắt đầu")))
A27: Tuần 7 | B27: 20/10 - 26/10/2026 | C27: 252 | D27: =COUNTIFS('📋 Báo Cáo 49 Ngày'!$B$5:$B$445, "Tuần " & 7, '📋 Báo Cáo 49 Ngày'!$G$5:$G$445, "<>") | E27: =COUNTIFS('📋 Báo Cáo 49 Ngày'!$B$5:$B$445, "Tuần " & 7, '📋 Báo Cáo 49 Ngày'!$I$5:$I$445, "<>") + COUNTIFS('📋 Báo Cáo 49 Ngày'!$B$5:$B$445, "Tuần " & 7, '📋 Báo Cáo 49 Ngày'!$K$5:$K$445, "<>") | F27: =COUNTIFS('📋 Báo Cáo 49 Ngày'!$B$5:$B$445, "Tuần " & 7, '📋 Báo Cáo 49 Ngày'!$M$5:$M$445, "<>") | G27: =D27+E27+F27 | H27: =IF(C27>0, G27/C27, 0) | I27: =IF(H27>=0.9, "✅ Về đích xuất sắc", IF(H27>=0.7, "⚡ Tiến độ ổn định", IF(H27>0, "⏳ Đang thực hiện", "⚪ Chưa bắt đầu")))

Sheet 📋 Báo Cáo 49 Ngày
A1: 📋 BẢNG BÁO CÁO CHI TIẾT 49 NGÀY - DÁN LINK & HÌNH ẢNH MINH CHỨNG
A3: 💡 Hướng dẫn: Thành viên dán Link Facebook hoặc Link Ảnh Drive/Chèn ảnh chụp màn hình vào các cột tương ứng. Hệ thống tự động đếm & tính % hoàn thành.
A4: STT | B4: Tuần | C4: Thứ | D4: Ngày | E4: Ngày Thứ | F4: Thành Viên | G4: Link Reel FB | H4: Ảnh Minh Chứng Reel | I4: Link Bài Viết 1 | J4: Ảnh Bài Viết 1 | K4: Link Bài Viết 2 | L4: Ảnh Bài Viết 2 | M4: Link Bài Tập Nhóm | N4: Ảnh Bài Tập Nhóm | O4: Hoàn Thành (/4) | P4: Trạng Thái Ngày
A5: 1 | B5: Tuần 1 | C5: Thứ 3 | D5: 08/09/2026 | E5: Ngày 01 | F5: Nancy | O5: =IF(OR(G5<>"",H5<>""),1,0) + IF(OR(I5<>"",J5<>""),1,0) + IF(OR(K5<>"",L5<>""),1,0) + IF(OR(M5<>"",N5<>""),1,0) | P5: =IF(O5=4,"✅ Đủ 4 nhiệm vụ",IF(O5>0,"⏳ Đạt "&O5&"/4","❌ Chưa nộp"))
A6: 2 | B6: Tuần 1 | C6: Thứ 3 | D6: 08/09/2026 | E6: Ngày 01 | F6: Hoài Học Mãi | O6: =IF(OR(G6<>"",H6<>""),1,0) + IF(OR(I6<>"",J6<>""),1,0) + IF(OR(K6<>"",L6<>""),1,0) + IF(OR(M6<>"",N6<>""),1,0) | P6: =IF(O6=4,"✅ Đủ 4 nhiệm vụ",IF(O6>0,"⏳ Đạt "&O6&"/4","❌ Chưa nộp"))
A7: 3 | B7: Tuần 1 | C7: Thứ 3 | D7: 08/09/2026 | E7: Ngày 01 | F7: Lambee | O7: =IF(OR(G7<>"",H7<>""),1,0) + IF(OR(I7<>"",J7<>""),1,0) + IF(OR(K7<>"",L7<>""),1,0) + IF(OR(M7<>"",N7<>""),1,0) | P7: =IF(O7=4,"✅ Đủ 4 nhiệm vụ",IF(O7>0,"⏳ Đạt "&O7&"/4","❌ Chưa nộp"))
A8: 4 | B8: Tuần 1 | C8: Thứ 3 | D8: 08/09/2026 | E8: Ngày 01 | F8: Nhung Hoàng | O8: =IF(OR(G8<>"",H8<>""),1,0) + IF(OR(I8<>"",J8<>""),1,0) + IF(OR(K8<>"",L8<>""),1,0) + IF(OR(M8<>"",N8<>""),1,0) | P8: =IF(O8=4,"✅ Đủ 4 nhiệm vụ",IF(O8>0,"⏳ Đạt "&O8&"/4","❌ Chưa nộp"))
A9: 5 | B9: Tuần 1 | C9: Thứ 3 | D9: 08/09/2026 | E9: Ngày 01 | F9: Quỳnh Thu | O9: =IF(OR(G9<>"",H9<>""),1,0) + IF(OR(I9<>"",J9<>""),1,0) + IF(OR(K9<>"",L9<>""),1,0) + IF(OR(M9<>"",N9<>""),1,0) | P9: =IF(O9=4,"✅ Đủ 4 nhiệm vụ",IF(O9>0,"⏳ Đạt "&O9&"/4","❌ Chưa nộp"))
A10: 6 | B10: Tuần 1 | C10: Thứ 3 | D10: 08/09/2026 | E10: Ngày 01 | F10: TanAnh Pham | O10: =IF(OR(G10<>"",H10<>""),1,0) + IF(OR(I10<>"",J10<>""),1,0) + IF(OR(K10<>"",L10<>""),1,0) + IF(OR(M10<>"",N10<>""),1,0) | P10: =IF(O10=4,"✅ Đủ 4 nhiệm vụ",IF(O10>0,"⏳ Đạt "&O10&"/4","❌ Chưa nộp"))
A11: 7 | B11: Tuần 1 | C11: Thứ 3 | D11: 08/09/2026 | E11: Ngày 01 | F11: Thảo Collins Edu | O11: =IF(OR(G11<>"",H11<>""),1,0) + IF(OR(I11<>"",J11<>""),1,0) + IF(OR(K11<>"",L11<>""),1,0) + IF(OR(M11<>"",N11<>""),1,0) | P11: =IF(O11=4,"✅ Đủ 4 nhiệm vụ",IF(O11>0,"⏳ Đạt "&O11&"/4","❌ Chưa nộp"))
A12: 8 | B12: Tuần 1 | C12: Thứ 3 | D12: 08/09/2026 | E12: Ngày 01 | F12: Trần Quế Lam | O12: =IF(OR(G12<>"",H12<>""),1,0) + IF(OR(I12<>"",J12<>""),1,0) + IF(OR(K12<>"",L12<>""),1,0) + IF(OR(M12<>"",N12<>""),1,0) | P12: =IF(O12=4,"✅ Đủ 4 nhiệm vụ",IF(O12>0,"⏳ Đạt "&O12&"/4","❌ Chưa nộp"))
A13: 9 | B13: Tuần 1 | C13: Thứ 3 | D13: 08/09/2026 | E13: Ngày 01 | F13: Phạm Huyền | O13: =IF(OR(G13<>"",H13<>""),1,0) + IF(OR(I13<>"",J13<>""),1,0) + IF(OR(K13<>"",L13<>""),1,0) + IF(OR(M13<>"",N13<>""),1,0) | P13: =IF(O13=4,"✅ Đủ 4 nhiệm vụ",IF(O13>0,"⏳ Đạt "&O13&"/4","❌ Chưa nộp"))
A14: 10 | B14: Tuần 1 | C14: Thứ 4 | D14: 09/09/2026 | E14: Ngày 02 | F14: Nancy | O14: =IF(OR(G14<>"",H14<>""),1,0) + IF(OR(I14<>"",J14<>""),1,0) + IF(OR(K14<>"",L14<>""),1,0) + IF(OR(M14<>"",N14<>""),1,0) | P14: =IF(O14=4,"✅ Đủ 4 nhiệm vụ",IF(O14>0,"⏳ Đạt "&O14&"/4","❌ Chưa nộp"))
A15: 11 | B15: Tuần 1 | C15: Thứ 4 | D15: 09/09/2026 | E15: Ngày 02 | F15: Hoài Học Mãi | O15: =IF(OR(G15<>"",H15<>""),1,0) + IF(OR(I15<>"",J15<>""),1,0) + IF(OR(K15<>"",L15<>""),1,0) + IF(OR(M15<>"",N15<>""),1,0) | P15: =IF(O15=4,"✅ Đủ 4 nhiệm vụ",IF(O15>0,"⏳ Đạt "&O15&"/4","❌ Chưa nộp"))
A16: 12 | B16: Tuần 1 | C16: Thứ 4 | D16: 09/09/2026 | E16: Ngày 02 | F16: Lambee | O16: =IF(OR(G16<>"",H16<>""),1,0) + IF(OR(I16<>"",J16<>""),1,0) + IF(OR(K16<>"",L16<>""),1,0) + IF(OR(M16<>"",N16<>""),1,0) | P16: =IF(O16=4,"✅ Đủ 4 nhiệm vụ",IF(O16>0,"⏳ Đạt "&O16&"/4","❌ Chưa nộp"))
... A445: 441 | B445: Tuần 7 | C445: Thứ 2 | D445: 26/10/2026 | E445: Ngày 49 | F445: Phạm Huyền | O445: =IF(OR(G445<>"",H445<>""),1,0) + IF(OR(I445<>"",J445<>""),1,0) + IF(OR(K445<>"",L445<>""),1,0) + IF(OR(M445<>"",N445<>""),1,0) | P445: =IF(O445=4,"✅ Đủ 4 nhiệm vụ",IF(O445>0,"⏳ Đạt "&O445&"/4","❌ Chưa nộp"))

Sheet Tuần 1
A1: 📅 TUẦN 1 (08/09 - 14/09/2026) - BÁO CÁO 9 THÀNH VIÊN
A4: 📍 THỨ 3 (08/09/2026) - NGÀY 01 / 49
A5: STT | B5: Thành Viên | C5: Reel (Link/Ảnh) | D5: Bài Viết 1 (Link/Ảnh) | E5: Bài Viết 2 (Link/Ảnh) | F5: Bài Tập Nhóm (Link/Ảnh) | G5: Chi Tiết Ảnh Minh Chứng | H5: Hoàn Thành | I5: Đánh Giá | J5: Ghi Chú
A6: 1 | B6: Nancy | C6: ='📋 Báo Cáo 49 Ngày'!G5 | D6: ='📋 Báo Cáo 49 Ngày'!I5 | E6: ='📋 Báo Cáo 49 Ngày'!K5 | F6: ='📋 Báo Cáo 49 Ngày'!M5 | G6: =IF(COUNTIF('📋 Báo Cáo 49 Ngày'!H5:N5, "<>")>0, "🖼️ Có kèm ảnh", "—") | H6: ='📋 Báo Cáo 49 Ngày'!O5 | I6: ='📋 Báo Cáo 49 Ngày'!P5
A7: 2 | B7: Hoài Học Mãi | C7: ='📋 Báo Cáo 49 Ngày'!G6 | D7: ='📋 Báo Cáo 49 Ngày'!I6 | E7: ='📋 Báo Cáo 49 Ngày'!K6 | F7: ='📋 Báo Cáo 49 Ngày'!M6 | G7: =IF(COUNTIF('📋 Báo Cáo 49 Ngày'!H6:N6, "<>")>0, "🖼️ Có kèm ảnh", "—") | H7: ='📋 Báo Cáo 49 Ngày'!O6 | I7: ='📋 Báo Cáo 49 Ngày'!P6
A8: 3 | B8: Lambee | C8: ='📋 Báo Cáo 49 Ngày'!G7 | D8: ='📋 Báo Cáo 49 Ngày'!I7 | E8: ='📋 Báo Cáo 49 Ngày'!K7 | F8: ='📋 Báo Cáo 49 Ngày'!M7 | G8: =IF(COUNTIF('📋 Báo Cáo 49 Ngày'!H7:N7, "<>")>0, "🖼️ Có kèm ảnh", "—") | H8: ='📋 Báo Cáo 49 Ngày'!O7 | I8: ='📋 Báo Cáo 49 Ngày'!P7
A9: 4 | B9: Nhung Hoàng | C9: ='📋 Báo Cáo 49 Ngày'!G8 | D9: ='📋 Báo Cáo 49 Ngày'!I8 | E9: ='📋 Báo Cáo 49 Ngày'!K8 | F9: ='📋 Báo Cáo 49 Ngày'!M8 | G9: =IF(COUNTIF('📋 Báo Cáo 49 Ngày'!H8:N8, "<>")>0, "🖼️ Có kèm ảnh", "—") | H9: ='📋 Báo Cáo 49 Ngày'!O8 | I9: ='📋 Báo Cáo 49 Ngày'!P8
A10: 5 | B10: Quỳnh Thu | C10: ='📋 Báo Cáo 49 Ngày'!G9 | D10: ='📋 Báo Cáo 49 Ngày'!I9 | E10: ='📋 Báo Cáo 49 Ngày'!K9 | F10: ='📋 Báo Cáo 49 Ngày'!M9 | G10: =IF(COUNTIF('📋 Báo Cáo 49 Ngày'!H9:N9, "<>")>0, "🖼️ Có kèm ảnh", "—") | H10: ='📋 Báo Cáo 49 Ngày'!O9 | I10: ='📋 Báo Cáo 49 Ngày'!P9
A11: 6 | B11: TanAnh Pham | C11: ='📋 Báo Cáo 49 Ngày'!G10 | D11: ='📋 Báo Cáo 49 Ngày'!I10 | E11: ='📋 Báo Cáo 49 Ngày'!K10 | F11: ='📋 Báo Cáo 49 Ngày'!M10 | G11: =IF(COUNTIF('📋 Báo Cáo 49 Ngày'!H10:N10, "<>")>0, "🖼️ Có kèm ảnh", "—") | H11: ='📋 Báo Cáo 49 Ngày'!O10 | I11: ='📋 Báo Cáo 49 Ngày'!P10
A12: 7 | B12: Thảo Collins Edu | C12: ='📋 Báo Cáo 49 Ngày'!G11 | D12: ='📋 Báo Cáo 49 Ngày'!I11 | E12: ='📋 Báo Cáo 49 Ngày'!K11 | F12: ='📋 Báo Cáo 49 Ngày'!M11 | G12: =IF(COUNTIF('📋 Báo Cáo 49 Ngày'!H11:N11, "<>")>0, "🖼️ Có kèm ảnh", "—") | H12: ='📋 Báo Cáo 49 Ngày'!O11 | I12: ='📋 Báo Cáo 49 Ngày'!P11
A13: 8 | B13: Trần Quế Lam | C13: ='📋 Báo Cáo 49 Ngày'!G12 | D13: ='📋 Báo Cáo 49 Ngày'!I12 | E13: ='📋 Báo Cáo 49 Ngày'!K12 | F13: ='📋 Báo Cáo 49 Ngày'!M12 | G13: =IF(COUNTIF('📋 Báo Cáo 49 Ngày'!H12:N12, "<>")>0, "🖼️ Có kèm ảnh", "—") | H13: ='📋 Báo Cáo 49 Ngày'!O12 | I13: ='📋 Báo Cáo 49 Ngày'!P12
A14: 9 | B14: Phạm Huyền | C14: ='📋 Báo Cáo 49 Ngày'!G13 | D14: ='📋 Báo Cáo 49 Ngày'!I13 | E14: ='📋 Báo Cáo 49 Ngày'!K13 | F14: ='📋 Báo Cáo 49 Ngày'!M13 | G14: =IF(COUNTIF('📋 Báo Cáo 49 Ngày'!H13:N13, "<>")>0, "🖼️ Có kèm ảnh", "—") | H14: ='📋 Báo Cáo 49 Ngày'!O13 | I14: ='📋 Báo Cáo 49 Ngày'!P13
A16: 📍 THỨ 4 (09/09/2026) - NGÀY 02 / 49
A17: STT | B17: Thành Viên | C17: Reel (Link/Ảnh) | D17: Bài Viết 1 (Link/Ảnh) | E17: Bài Viết 2 (Link/Ảnh) | F17: Bài Tập Nhóm (Link/Ảnh) | G17: Chi Tiết Ảnh Minh Chứng | H17: Hoàn Thành | I17: Đánh Giá | J17: Ghi Chú
A18: 1 | B18: Nancy | C18: ='📋 Báo Cáo 49 Ngày'!G14 | D18: ='📋 Báo Cáo 49 Ngày'!I14 | E18: ='📋 Báo Cáo 49 Ngày'!K14 | F18: ='📋 Báo Cáo 49 Ngày'!M14 | G18: =IF(COUNTIF('📋 Báo Cáo 49 Ngày'!H14:N14, "<>")>0, "🖼️ Có kèm ảnh", "—") | H18: ='📋 Báo Cáo 49 Ngày'!O14 | I18: ='📋 Báo Cáo 49 Ngày'!P14
A19: 2 | B19: Hoài Học Mãi | C19: ='📋 Báo Cáo 49 Ngày'!G15 | D19: ='📋 Báo Cáo 49 Ngày'!I15 | E19: ='📋 Báo Cáo 49 Ngày'!K15 | F19: ='📋 Báo Cáo 49 Ngày'!M15 | G19: =IF(COUNTIF('📋 Báo Cáo 49 Ngày'!H15:N15, "<>")>0, "🖼️ Có kèm ảnh", "—") | H19: ='📋 Báo Cáo 49 Ngày'!O15 | I19: ='📋 Báo Cáo 49 Ngày'!P15
A20: 3 | B20: Lambee | C20: ='📋 Báo Cáo 49 Ngày'!G16 | D20: ='📋 Báo Cáo 49 Ngày'!I16 | E20: ='📋 Báo Cáo 49 Ngày'!K16 | F20: ='📋 Báo Cáo 49 Ngày'!M16 | G20: =IF(COUNTIF('📋 Báo Cáo 49 Ngày'!H16:N16, "<>")>0, "🖼️ Có kèm ảnh", "—") | H20: ='📋 Báo Cáo 49 Ngày'!O16 | I20: ='📋 Báo Cáo 49 Ngày'!P16
A21: 4 | B21: Nhung Hoàng | C21: ='📋 Báo Cáo 49 Ngày'!G17 | D21: ='📋 Báo Cáo 49 Ngày'!I17 | E21: ='📋 Báo Cáo 49 Ngày'!K17 | F21: ='📋 Báo Cáo 49 Ngày'!M17 | G21: =IF(COUNTIF('📋 Báo Cáo 49 Ngày'!H17:N17, "<>")>0, "🖼️ Có kèm ảnh", "—") | H21: ='📋 Báo Cáo 49 Ngày'!O17 | I21: ='📋 Báo Cáo 49 Ngày'!P17
A22: 5 | B22: Quỳnh Thu | C22: ='📋 Báo Cáo 49 Ngày'!G18 | D22: ='📋 Báo Cáo 49 Ngày'!I18 | E22: ='📋 Báo Cáo 49 Ngày'!K18 | F22: ='📋 Báo Cáo 49 Ngày'!M18 | G22: =IF(COUNTIF('📋 Báo Cáo 49 Ngày'!H18:N18, "<>")>0, "🖼️ Có kèm ảnh", "—") | H22: ='📋 Báo Cáo 49 Ngày'!O18 | I22: ='📋 Báo Cáo 49 Ngày'!P18
A23: 6 | B23: TanAnh Pham | C23: ='📋 Báo Cáo 49 Ngày'!G19 | D23: ='📋 Báo Cáo 49 Ngày'!I19 | E23: ='📋 Báo Cáo 49 Ngày'!K19 | F23: ='📋 Báo Cáo 49 Ngày'!M19 | G23: =IF(COUNTIF('📋 Báo Cáo 49 Ngày'!H19:N19, "<>")>0, "🖼️ Có kèm ảnh", "—") | H23: ='📋 Báo Cáo 49 Ngày'!O19 | I23: ='📋 Báo Cáo 49 Ngày'!P19
A24: 7 | B24: Thảo Collins Edu | C24: ='📋 Báo Cáo 49 Ngày'!G20 | D24: ='📋 Báo Cáo 49 Ngày'!I20 | E24: ='📋 Báo Cáo 49 Ngày'!K20 | F24: ='📋 Báo Cáo 49 Ngày'!M20 | G24: =IF(COUNTIF('📋 Báo Cáo 49 Ngày'!H20:N20, "<>")>0, "🖼️ Có kèm ảnh", "—") | H24: ='📋 Báo Cáo 49 Ngày'!O20 | I24: ='📋 Báo Cáo 49 Ngày'!P20
A25: 8 | B25: Trần Quế Lam | C25: ='📋 Báo Cáo 49 Ngày'!G21 | D25: ='📋 Báo Cáo 49 Ngày'!I21 | E25: ='📋 Báo Cáo 49 Ngày'!K21 | F25: ='📋 Báo Cáo 49 Ngày'!M21 | G25: =IF(COUNTIF('📋 Báo Cáo 49 Ngày'!H21:N21, "<>")>0, "🖼️ Có kèm ảnh", "—") | H25: ='📋 Báo Cáo 49 Ngày'!O21 | I25: ='📋 Báo Cáo 49 Ngày'!P21
A26: 9 | B26: Phạm Huyền | C26: ='📋 Báo Cáo 49 Ngày'!G22 | D26: ='📋 Báo Cáo 49 Ngày'!I22 | E26: ='📋 Báo Cáo 49 Ngày'!K22 | F26: ='📋 Báo Cáo 49 Ngày'!M22 | G26: =IF(COUNTIF('📋 Báo Cáo 49 Ngày'!H22:N22, "<>")>0, "🖼️ Có kèm ảnh", "—") | H26: ='📋 Báo Cáo 49 Ngày'!O22 | I26: ='📋 Báo Cáo 49 Ngày'!P22
A28: 📍 THỨ 5 (10/09/2026) - NGÀY 03 / 49
A29: STT | B29: Thành Viên | C29: Reel (Link/Ảnh) | D29: Bài Viết 1 (Link/Ảnh) | E29: Bài Viết 2 (Link/Ảnh) | F29: Bài Tập Nhóm (Link/Ảnh) | G29: Chi Tiết Ảnh Minh Chứng | H29: Hoàn Thành | I29: Đánh Giá | J29: Ghi Chú
A30: 1 | B30: Nancy | C30: ='📋 Báo Cáo 49 Ngày'!G23 | D30: ='📋 Báo Cáo 49 Ngày'!I23 | E30: ='📋 Báo Cáo 49 Ngày'!K23 | F30: ='📋 Báo Cáo 49 Ngày'!M23 | G30: =IF(COUNTIF('📋 Báo Cáo 49 Ngày'!H23:N23, "<>")>0, "🖼️ Có kèm ảnh", "—") | H30: ='📋 Báo Cáo 49 Ngày'!O23 | I30: ='📋 Báo Cáo 49 Ngày'!P23
A31: 2 | B31: Hoài Học Mãi | C31: ='📋 Báo Cáo 49 Ngày'!G24 | D31: ='📋 Báo Cáo 49 Ngày'!I24 | E31: ='📋 Báo Cáo 49 Ngày'!K24 | F31: ='📋 Báo Cáo 49 Ngày'!M24 | G31: =IF(COUNTIF('📋 Báo Cáo 49 Ngày'!H24:N24, "<>")>0, "🖼️ Có kèm ảnh", "—") | H31: ='📋 Báo Cáo 49 Ngày'!O24 | I31: ='📋 Báo Cáo 49 Ngày'!P24
A32: 3 | B32: Lambee | C32: ='📋 Báo Cáo 49 Ngày'!G25 | D32: ='📋 Báo Cáo 49 Ngày'!I25 | E32: ='📋 Báo Cáo 49 Ngày'!K25 | F32: ='📋 Báo Cáo 49 Ngày'!M25 | G32: =IF(COUNTIF('📋 Báo Cáo 49 Ngày'!H25:N25, "<>")>0, "🖼️ Có kèm ảnh", "—") | H32: ='📋 Báo Cáo 49 Ngày'!O25 | I32: ='📋 Báo Cáo 49 Ngày'!P25
A33: 4 | B33: Nhung Hoàng | C33: ='📋 Báo Cáo 49 Ngày'!G26 | D33: ='📋 Báo Cáo 49 Ngày'!I26 | E33: ='📋 Báo Cáo 49 Ngày'!K26 | F33: ='📋 Báo Cáo 49 Ngày'!M26 | G33: =IF(COUNTIF('📋 Báo Cáo 49 Ngày'!H26:N26, "<>")>0, "🖼️ Có kèm ảnh", "—") | H33: ='📋 Báo Cáo 49 Ngày'!O26 | I33: ='📋 Báo Cáo 49 Ngày'!P26
A34: 5 | B34: Quỳnh Thu | C34: ='📋 Báo Cáo 49 Ngày'!G27 | D34: ='📋 Báo Cáo 49 Ngày'!I27 | E34: ='📋 Báo Cáo 49 Ngày'!K27 | F34: ='📋 Báo Cáo 49 Ngày'!M27 | G34: =IF(COUNTIF('📋 Báo Cáo 49 Ngày'!H27:N27, "<>")>0, "🖼️ Có kèm ảnh", "—") | H34: ='📋 Báo Cáo 49 Ngày'!O27 | I34: ='📋 Báo Cáo 49 Ngày'!P27
A35: 6 | B35: TanAnh Pham | C35: ='📋 Báo Cáo 49 Ngày'!G28 | D35: ='📋 Báo Cáo 49 Ngày'!I28 | E35: ='📋 Báo Cáo 49 Ngày'!K28 | F35: ='📋 Báo Cáo 49 Ngày'!M28 | G35: =IF(COUNTIF('📋 Báo Cáo 49 Ngày'!H28:N28, "<>")>0, "🖼️ Có kèm ảnh", "—") | H35: ='📋 Báo Cáo 49 Ngày'!O28 | I35: ='📋 Báo Cáo 49 Ngày'!P28
A36: 7 | B36: Thảo Collins Edu | C36: ='📋 Báo Cáo 49 Ngày'!G29 | D36: ='📋 Báo Cáo 49 Ngày'!I29 | E36: ='📋 Báo Cáo 49 Ngày'!K29 | F36: ='📋 Báo Cáo 49 Ngày'!M29 | G36: =IF(COUNTIF('📋 Báo Cáo 49 Ngày'!H29:N29, "<>")>0, "🖼️ Có kèm ảnh", "—") | H36: ='📋 Báo Cáo 49 Ngày'!O29 | I36: ='📋 Báo Cáo 49 Ngày'!P29
A37: 8 | B37: Trần Quế Lam | C37: ='📋 Báo Cáo 49 Ngày'!G30 | D37: ='📋 Báo Cáo 49 Ngày'!I30 | E37: ='📋 Báo Cáo 49 Ngày'!K30 | F37: ='📋 Báo Cáo 49 Ngày'!M30 | G37: =IF(COUNTIF('📋 Báo Cáo 49 Ngày'!H30:N30, "<>")>0, "🖼️ Có kèm ảnh", "—") | H37: ='📋 Báo Cáo 49 Ngày'!O30 | I37: ='📋 Báo Cáo 49 Ngày'!P30
A38: 9 | B38: Phạm Huyền | C38: ='📋 Báo Cáo 49 Ngày'!G31 | D38: ='📋 Báo Cáo 49 Ngày'!I31 | E38: ='📋 Báo Cáo 49 Ngày'!K31 | F38: ='📋 Báo Cáo 49 Ngày'!M31 | G38: =IF(COUNTIF('📋 Báo Cáo 49 Ngày'!H31:N31, "<>")>0, "🖼️ Có kèm ảnh", "—") | H38: ='📋 Báo Cáo 49 Ngày'!O31 | I38: ='📋 Báo Cáo 49 Ngày'!P31
A40: 📍 THỨ 6 (11/09/2026) - NGÀY 04 / 49
A41: STT | B41: Thành Viên | C41: Reel (Link/Ảnh) | D41: Bài Viết 1 (Link/Ảnh) | E41: Bài Viết 2 (Link/Ảnh) | F41: Bài Tập Nhóm (Link/Ảnh) | G41: Chi Tiết Ảnh Minh Chứng | H41: Hoàn Thành | I41: Đánh Giá | J41: Ghi Chú
A42: 1 | B42: Nancy | C42: ='📋 Báo Cáo 49 Ngày'!G32 | D42: ='📋 Báo Cáo 49 Ngày'!I32 | E42: ='📋 Báo Cáo 49 Ngày'!K32 | F42: ='📋 Báo Cáo 49 Ngày'!M32 | G42: =IF(COUNTIF('📋 Báo Cáo 49 Ngày'!H32:N32, "<>")>0, "🖼️ Có kèm ảnh", "—") | H42: ='📋 Báo Cáo 49 Ngày'!O32 | I42: ='📋 Báo Cáo 49 Ngày'!P32
A43: 2 | B43: Hoài Học Mãi | C43: ='📋 Báo Cáo 49 Ngày'!G33 | D43: ='📋 Báo Cáo 49 Ngày'!I33 | E43: ='📋 Báo Cáo 49 Ngày'!K33 | F43: ='📋 Báo Cáo 49 Ngày'!M33 | G43: =IF(COUNTIF('📋 Báo Cáo 49 Ngày'!H33:N33, "<>")>0, "🖼️ Có kèm ảnh", "—") | H43: ='📋 Báo Cáo 49 Ngày'!O33 | I43: ='📋 Báo Cáo 49 Ngày'!P33
A44: 3 | B44: Lambee | C44: ='📋 Báo Cáo 49 Ngày'!G34 | D44: ='📋 Báo Cáo 49 Ngày'!I34 | E44: ='📋 Báo Cáo 49 Ngày'!K34 | F44: ='📋 Báo Cáo 49 Ngày'!M34 | G44: =IF(COUNTIF('📋 Báo Cáo 49 Ngày'!H34:N34, "<>")>0, "🖼️ Có kèm ảnh", "—") | H44: ='📋 Báo Cáo 49 Ngày'!O34 | I44: ='📋 Báo Cáo 49 Ngày'!P34
A45: 4 | B45: Nhung Hoàng | C45: ='📋 Báo Cáo 49 Ngày'!G35 | D45: ='📋 Báo Cáo 49 Ngày'!I35 | E45: ='📋 Báo Cáo 49 Ngày'!K35 | F45: ='📋 Báo Cáo 49 Ngày'!M35 | G45: =IF(COUNTIF('📋 Báo Cáo 49 Ngày'!H35:N35, "<>")>0, "🖼️ Có kèm ảnh", "—") | H45: ='📋 Báo Cáo 49 Ngày'!O35 | I45: ='📋 Báo Cáo 49 Ngày'!P35
...

Sheet Tuần 2
A1: 📅 TUẦN 2 (15/09 - 21/09/2026) - BÁO CÁO 9 THÀNH VIÊN
A4: 📍 THỨ 3 (15/09/2026) - NGÀY 08 / 49
A5: STT | B5: Thành Viên | C5: Reel (Link/Ảnh) | D5: Bài Viết 1 (Link/Ảnh) | E5: Bài Viết 2 (Link/Ảnh) | F5: Bài Tập Nhóm (Link/Ảnh) | G5: Chi Tiết Ảnh Minh Chứng | H5: Hoàn Thành | I5: Đánh Giá | J5: Ghi Chú
A6: 1 | B6: Nancy | C6: ='📋 Báo Cáo 49 Ngày'!G68 | D6: ='📋 Báo Cáo 49 Ngày'!I68 | E6: ='📋 Báo Cáo 49 Ngày'!K68 | F6: ='📋 Báo Cáo 49 Ngày'!M68 | G6: =IF(COUNTIF('📋 Báo Cáo 49 Ngày'!H68:N68, "<>")>0, "🖼️ Có kèm ảnh", "—") | H6: ='📋 Báo Cáo 49 Ngày'!O68 | I6: ='📋 Báo Cáo 49 Ngày'!P68
A7: 2 | B7: Hoài Học Mãi | C7: ='📋 Báo Cáo 49 Ngày'!G69 | D7: ='📋 Báo Cáo 49 Ngày'!I69 | E7: ='📋 Báo Cáo 49 Ngày'!K69 | F7: ='📋 Báo Cáo 49 Ngày'!M69 | G7: =IF(COUNTIF('📋 Báo Cáo 49 Ngày'!H69:N69, "<>")>0, "🖼️ Có kèm ảnh", "—") | H7: ='📋 Báo Cáo 49 Ngày'!O69 | I7: ='📋 Báo Cáo 49 Ngày'!P69
A8: 3 | B8: Lambee | C8: ='📋 Báo Cáo 49 Ngày'!G70 | D8: ='📋 Báo Cáo 49 Ngày'!I70 | E8: ='📋 Báo Cáo 49 Ngày'!K70 | F8: ='📋 Báo Cáo 49 Ngày'!M70 | G8: =IF(COUNTIF('📋 Báo Cáo 49 Ngày'!H70:N70, "<>")>0, "🖼️ Có kèm ảnh", "—") | H8: ='📋 Báo Cáo 49 Ngày'!O70 | I8: ='📋 Báo Cáo 49 Ngày'!P70
A9: 4 | B9: Nhung Hoàng | C9: ='📋 Báo Cáo 49 Ngày'!G71 | D9: ='📋 Báo Cáo 49 Ngày'!I71 | E9: ='📋 Báo Cáo 49 Ngày'!K71 | F9: ='📋 Báo Cáo 49 Ngày'!M71 | G9: =IF(COUNTIF('📋 Báo Cáo 49 Ngày'!H71:N71, "<>")>0, "🖼️ Có kèm ảnh", "—") | H9: ='📋 Báo Cáo 49 Ngày'!O71 | I9: ='📋 Báo Cáo 49 Ngày'!P71
A10: 5 | B10: Quỳnh Thu | C10: ='📋 Báo Cáo 49 Ngày'!G72 | D10: ='📋 Báo Cáo 49 Ngày'!I72 | E10: ='📋 Báo Cáo 49 Ngày'!K72 | F10: ='📋 Báo Cáo 49 Ngày'!M72 | G10: =IF(COUNTIF('📋 Báo Cáo 49 Ngày'!H72:N72, "<>")>0, "🖼️ Có kèm ảnh", "—") | H10: ='📋 Báo Cáo 49 Ngày'!O72 | I10: ='📋 Báo Cáo 49 Ngày'!P72
A11: 6 | B11: TanAnh Pham | C11: ='📋 Báo Cáo 49 Ngày'!G73 | D11: ='📋 Báo Cáo 49 Ngày'!I73 | E11: ='📋 Báo Cáo 49 Ngày'!K73 | F11: ='📋 Báo Cáo 49 Ngày'!M73 | G11: =IF(COUNTIF('📋 Báo Cáo 49 Ngày'!H73:N73, "<>")>0, "🖼️ Có kèm ảnh", "—") | H11: ='📋 Báo Cáo 49 Ngày'!O73 | I11: ='📋 Báo Cáo 49 Ngày'!P73
A12: 7 | B12: Thảo Collins Edu | C12: ='📋 Báo Cáo 49 Ngày'!G74 | D12: ='📋 Báo Cáo 49 Ngày'!I74 | E12: ='📋 Báo Cáo 49 Ngày'!K74 | F12: ='📋 Báo Cáo 49 Ngày'!M74 | G12: =IF(COUNTIF('📋 Báo Cáo 49 Ngày'!H74:N74, "<>")>0, "🖼️ Có kèm ảnh", "—") | H12: ='📋 Báo Cáo 49 Ngày'!O74 | I12: ='📋 Báo Cáo 49 Ngày'!P74
A13: 8 | B13: Trần Quế Lam | C13: ='📋 Báo Cáo 49 Ngày'!G75 | D13: ='📋 Báo Cáo 49 Ngày'!I75 | E13: ='📋 Báo Cáo 49 Ngày'!K75 | F13: ='📋 Báo Cáo 49 Ngày'!M75 | G13: =IF(COUNTIF('📋 Báo Cáo 49 Ngày'!H75:N75, "<>")>0, "🖼️ Có kèm ảnh", "—") | H13: ='📋 Báo Cáo 49 Ngày'!O75 | I13: ='📋 Báo Cáo 49 Ngày'!P75
A14: 9 | B14: Phạm Huyền | C14: ='📋 Báo Cáo 49 Ngày'!G76 | D14: ='📋 Báo Cáo 49 Ngày'!I76 | E14: ='📋 Báo Cáo 49 Ngày'!K76 | F14: ='📋 Báo Cáo 49 Ngày'!M76 | G14: =IF(COUNTIF('📋 Báo Cáo 49 Ngày'!H76:N76, "<>")>0, "🖼️ Có kèm ảnh", "—") | H14: ='📋 Báo Cáo 49 Ngày'!O76 | I14: ='📋 Báo Cáo 49 Ngày'!P76
A16: 📍 THỨ 4 (16/09/2026) - NGÀY 09 / 49
A17: STT | B17: Thành Viên | C17: Reel (Link/Ảnh) | D17: Bài Viết 1 (Link/Ảnh) | E17: Bài Viết 2 (Link/Ảnh) | F17: Bài Tập Nhóm (Link/Ảnh) | G17: Chi Tiết Ảnh Minh Chứng | H17: Hoàn Thành | I17: Đánh Giá | J17: Ghi Chú
A18: 1 | B18: Nancy | C18: ='📋 Báo Cáo 49 Ngày'!G77 | D18: ='📋 Báo Cáo 49 Ngày'!I77 | E18: ='📋 Báo Cáo 49 Ngày'!K77 | F18: ='📋 Báo Cáo 49 Ngày'!M77 | G18: =IF(COUNTIF('📋 Báo Cáo 49 Ngày'!H77:N77, "<>")>0, "🖼️ Có kèm ảnh", "—") | H18: ='📋 Báo Cáo 49 Ngày'!O77 | I18: ='📋 Báo Cáo 49 Ngày'!P77
A19: 2 | B19: Hoài Học Mãi | C19: ='📋 Báo Cáo 49 Ngày'!G78 | D19: ='📋 Báo Cáo 49 Ngày'!I78 | E19: ='📋 Báo Cáo 49 Ngày'!K78 | F19: ='📋 Báo Cáo 49 Ngày'!M78 | G19: =IF(COUNTIF('📋 Báo Cáo 49 Ngày'!H78:N78, "<>")>0, "🖼️ Có kèm ảnh", "—") | H19: ='📋 Báo Cáo 49 Ngày'!O78 | I19: ='📋 Báo Cáo 49 Ngày'!P78
A20: 3 | B20: Lambee | C20: ='📋 Báo Cáo 49 Ngày'!G79 | D20: ='📋 Báo Cáo 49 Ngày'!I79 | E20: ='📋 Báo Cáo 49 Ngày'!K79 | F20: ='📋 Báo Cáo 49 Ngày'!M79 | G20: =IF(COUNTIF('📋 Báo Cáo 49 Ngày'!H79:N79, "<>")>0, "🖼️ Có kèm ảnh", "—") | H20: ='📋 Báo Cáo 49 Ngày'!O79 | I20: ='📋 Báo Cáo 49 Ngày'!P79
A21: 4 | B21: Nhung Hoàng | C21: ='📋 Báo Cáo 49 Ngày'!G80 | D21: ='📋 Báo Cáo 49 Ngày'!I80 | E21: ='📋 Báo Cáo 49 Ngày'!K80 | F21: ='📋 Báo Cáo 49 Ngày'!M80 | G21: =IF(COUNTIF('📋 Báo Cáo 49 Ngày'!H80:N80, "<>")>0, "🖼️ Có kèm ảnh", "—") | H21: ='📋 Báo Cáo 49 Ngày'!O80 | I21: ='📋 Báo Cáo 49 Ngày'!P80
A22: 5 | B22: Quỳnh Thu | C22: ='📋 Báo Cáo 49 Ngày'!G81 | D22: ='📋 Báo Cáo 49 Ngày'!I81 | E22: ='📋 Báo Cáo 49 Ngày'!K81 | F22: ='📋 Báo Cáo 49 Ngày'!M81 | G22: =IF(COUNTIF('📋 Báo Cáo 49 Ngày'!H81:N81, "<>")>0, "🖼️ Có kèm ảnh", "—") | H22: ='📋 Báo Cáo 49 Ngày'!O81 | I22: ='📋 Báo Cáo 49 Ngày'!P81
A23: 6 | B23: TanAnh Pham | C23: ='📋 Báo Cáo 49 Ngày'!G82 | D23: ='📋 Báo Cáo 49 Ngày'!I82 | E23: ='📋 Báo Cáo 49 Ngày'!K82 | F23: ='📋 Báo Cáo 49 Ngày'!M82 | G23: =IF(COUNTIF('📋 Báo Cáo 49 Ngày'!H82:N82, "<>")>0, "🖼️ Có kèm ảnh", "—") | H23: ='📋 Báo Cáo 49 Ngày'!O82 | I23: ='📋 Báo Cáo 49 Ngày'!P82
A24: 7 | B24: Thảo Collins Edu | C24: ='📋 Báo Cáo 49 Ngày'!G83 | D24: ='📋 Báo Cáo 49 Ngày'!I83 | E24: ='📋 Báo Cáo 49 Ngày'!K83 | F24: ='📋 Báo Cáo 49 Ngày'!M83 | G24: =IF(COUNTIF('📋 Báo Cáo 49 Ngày'!H83:N83, "<>")>0, "🖼️ Có kèm ảnh", "—") | H24: ='📋 Báo Cáo 49 Ngày'!O83 | I24: ='📋 Báo Cáo 49 Ngày'!P83
A25: 8 | B25: Trần Quế Lam | C25: ='📋 Báo Cáo 49 Ngày'!G84 | D25: ='📋 Báo Cáo 49 Ngày'!I84 | E25: ='📋 Báo Cáo 49 Ngày'!K84 | F25: ='📋 Báo Cáo 49 Ngày'!M84 | G25: =IF(COUNTIF('📋 Báo Cáo 49 Ngày'!H84:N84, "<>")>0, "🖼️ Có kèm ảnh", "—") | H25: ='📋 Báo Cáo 49 Ngày'!O84 | I25: ='📋 Báo Cáo 49 Ngày'!P84
A26: 9 | B26: Phạm Huyền | C26: ='📋 Báo Cáo 49 Ngày'!G85 | D26: ='📋 Báo Cáo 49 Ngày'!I85 | E26: ='📋 Báo Cáo 49 Ngày'!K85 | F26: ='📋 Báo Cáo 49 Ngày'!M85 | G26: =IF(COUNTIF('📋 Báo Cáo 49 Ngày'!H85:N85, "<>")>0, "🖼️ Có kèm ảnh", "—") | H26: ='📋 Báo Cáo 49 Ngày'!O85 | I26: ='📋 Báo Cáo 49 Ngày'!P85
A28: 📍 THỨ 5 (17/09/2026) - NGÀY 10 / 49
A29: STT | B29: Thành Viên | C29: Reel (Link/Ảnh) | D29: Bài Viết 1 (Link/Ảnh) | E29: Bài Viết 2 (Link/Ảnh) | F29: Bài Tập Nhóm (Link/Ảnh) | G29: Chi Tiết Ảnh Minh Chứng | H29: Hoàn Thành | I29: Đánh Giá | J29: Ghi Chú
A30: 1 | B30: Nancy | C30: ='📋 Báo Cáo 49 Ngày'!G86 | D30: ='📋 Báo Cáo 49 Ngày'!I86 | E30: ='📋 Báo Cáo 49 Ngày'!K86 | F30: ='📋 Báo Cáo 49 Ngày'!M86 | G30: =IF(COUNTIF('📋 Báo Cáo 49 Ngày'!H86:N86, "<>")>0, "🖼️ Có kèm ảnh", "—") | H30: ='📋 Báo Cáo 49 Ngày'!O86 | I30: ='📋 Báo Cáo 49 Ngày'!P86
A31: 2 | B31: Hoài Học Mãi | C31: ='📋 Báo Cáo 49 Ngày'!G87 | D31: ='📋 Báo Cáo 49 Ngày'!I87 | E31: ='📋 Báo Cáo 49 Ngày'!K87 | F31: ='📋 Báo Cáo 49 Ngày'!M87 | G31: =IF(COUNTIF('📋 Báo Cáo 49 Ngày'!H87:N87, "<>")>0, "🖼️ Có kèm ảnh", "—") | H31: ='📋 Báo Cáo 49 Ngày'!O87 | I31: ='📋 Báo Cáo 49 Ngày'!P87
A32: 3 | B32: Lambee | C32: ='📋 Báo Cáo 49 Ngày'!G88 | D32: ='📋 Báo Cáo 49 Ngày'!I88 | E32: ='📋 Báo Cáo 49 Ngày'!K88 | F32: ='📋 Báo Cáo 49 Ngày'!M88 | G32: =IF(COUNTIF('📋 Báo Cáo 49 Ngày'!H88:N88, "<>")>0, "🖼️ Có kèm ảnh", "—") | H32: ='📋 Báo Cáo 49 Ngày'!O88 | I32: ='📋 Báo Cáo 49 Ngày'!P88
A33: 4 | B33: Nhung Hoàng | C33: ='📋 Báo Cáo 49 Ngày'!G89 | D33: ='📋 Báo Cáo 49 Ngày'!I89 | E33: ='📋 Báo Cáo 49 Ngày'!K89 | F33: ='📋 Báo Cáo 49 Ngày'!M89 | G33: =IF(COUNTIF('📋 Báo Cáo 49 Ngày'!H89:N89, "<>")>0, "🖼️ Có kèm ảnh", "—") | H33: ='📋 Báo Cáo 49 Ngày'!O89 | I33: ='📋 Báo Cáo 49 Ngày'!P89
A34: 5 | B34: Quỳnh Thu | C34: ='📋 Báo Cáo 49 Ngày'!G90 | D34: ='📋 Báo Cáo 49 Ngày'!I90 | E34: ='📋 Báo Cáo 49 Ngày'!K90 | F34: ='📋 Báo Cáo 49 Ngày'!M90 | G34: =IF(COUNTIF('📋 Báo Cáo 49 Ngày'!H90:N90, "<>")>0, "🖼️ Có kèm ảnh", "—") | H34: ='📋 Báo Cáo 49 Ngày'!O90 | I34: ='📋 Báo Cáo 49 Ngày'!P90
A35: 6 | B35: TanAnh Pham | C35: ='📋 Báo Cáo 49 Ngày'!G91 | D35: ='📋 Báo Cáo 49 Ngày'!I91 | E35: ='📋 Báo Cáo 49 Ngày'!K91 | F35: ='📋 Báo Cáo 49 Ngày'!M91 | G35: =IF(COUNTIF('📋 Báo Cáo 49 Ngày'!H91:N91, "<>")>0, "🖼️ Có kèm ảnh", "—") | H35: ='📋 Báo Cáo 49 Ngày'!O91 | I35: ='📋 Báo Cáo 49 Ngày'!P91
A36: 7 | B36: Thảo Collins Edu | C36: ='📋 Báo Cáo 49 Ngày'!G92 | D36: ='📋 Báo Cáo 49 Ngày'!I92 | E36: ='📋 Báo Cáo 49 Ngày'!K92 | F36: ='📋 Báo Cáo 49 Ngày'!M92 | G36: =IF(COUNTIF('📋 Báo Cáo 49 Ngày'!H92:N92, "<>")>0, "🖼️ Có kèm ảnh", "—") | H36: ='📋 Báo Cáo 49 Ngày'!O92 | I36: ='📋 Báo Cáo 49 Ngày'!P92
A37: 8 | B37: Trần Quế Lam | C37: ='📋 Báo Cáo 49 Ngày'!G93 | D37: ='📋 Báo Cáo 49 Ngày'!I93 | E37: ='📋 Báo Cáo 49 Ngày'!K93 | F37: ='📋 Báo Cáo 49 Ngày'!M93 | G37: =IF(COUNTIF('📋 Báo Cáo 49 Ngày'!H93:N93, "<>")>0, "🖼️ Có kèm ảnh", "—") | H37: ='📋 Báo Cáo 49 Ngày'!O93 | I37: ='📋 Báo Cáo 49 Ngày'!P93
A38: 9 | B38: Phạm Huyền | C38: ='📋 Báo Cáo 49 Ngày'!G94 | D38: ='📋 Báo Cáo 49 Ngày'!I94 | E38: ='📋 Báo Cáo 49 Ngày'!K94 | F38: ='📋 Báo Cáo 49 Ngày'!M94 | G38: =IF(COUNTIF('📋 Báo Cáo 49 Ngày'!H94:N94, "<>")>0, "🖼️ Có kèm ảnh", "—") | H38: ='📋 Báo Cáo 49 Ngày'!O94 | I38: ='📋 Báo Cáo 49 Ngày'!P94
A40: 📍 THỨ 6 (18/09/2026) - NGÀY 11 / 49
A41: STT | B41: Thành Viên | C41: Reel (Link/Ảnh) | D41: Bài Viết 1 (Link/Ảnh) | E41: Bài Viết 2 (Link/Ảnh) | F41: Bài Tập Nhóm (Link/Ảnh) | G41: Chi Tiết Ảnh Minh Chứng | H41: Hoàn Thành | I41: Đánh Giá | J41: Ghi Chú
A42: 1 | B42: Nancy | C42: ='📋 Báo Cáo 49 Ngày'!G95 | D42: ='📋 Báo Cáo 49 Ngày'!I95 | E42: ='📋 Báo Cáo 49 Ngày'!K95 | F42: ='📋 Báo Cáo 49 Ngày'!M95 | G42: =IF(COUNTIF('📋 Báo Cáo 49 Ngày'!H95:N95, "<>")>0, "🖼️ Có kèm ảnh", "—") | H42: ='📋 Báo Cáo 49 Ngày'!O95 | I42: ='📋 Báo Cáo 49 Ngày'!P95
A43: 2 | B43: Hoài Học Mãi | C43: ='📋 Báo Cáo 49 Ngày'!G96 | D43: ='📋 Báo Cáo 49 Ngày'!I96 | E43: ='📋 Báo Cáo 49 Ngày'!K96 | F43: ='📋 Báo Cáo 49 Ngày'!M96 | G43: =IF(COUNTIF('📋 Báo Cáo 49 Ngày'!H96:N96, "<>")>0, "🖼️ Có kèm ảnh", "—") | H43: ='📋 Báo Cáo 49 Ngày'!O96 | I43: ='📋 Báo Cáo 49 Ngày'!P96
A44: 3 | B44: Lambee | C44: ='📋 Báo Cáo 49 Ngày'!G97 | D44: ='📋 Báo Cáo 49 Ngày'!I97 | E44: ='📋 Báo Cáo 49 Ngày'!K97 | F44: ='📋 Báo Cáo 49 Ngày'!M97 | G44: =IF(COUNTIF('📋 Báo Cáo 49 Ngày'!H97:N97, "<>")>0, "🖼️ Có kèm ảnh", "—") | H44: ='📋 Báo Cáo 49 Ngày'!O97 | I44: ='📋 Báo Cáo 49 Ngày'!P97
A45: 4 | B45: Nhung Hoàng | C45: ='📋 Báo Cáo 49 Ngày'!G98 | D45: ='📋 Báo Cáo 49 Ngày'!I98 | E45: ='📋 Báo Cáo 49 Ngày'!K98 | F45: ='📋 Báo Cáo 49 Ngày'!M98 | G45: =IF(COUNTIF('📋 Báo Cáo 49 Ngày'!H98:N98, "<>")>0, "🖼️ Có kèm ảnh", "—") | H45: ='📋 Báo Cáo 49 Ngày'!O98 | I45: ='📋 Báo Cáo 49 Ngày'!P98
...

Sheet Tuần 3
A1: 📅 TUẦN 3 (22/09 - 28/09/2026) - BÁO CÁO 9 THÀNH VIÊN
A4: 📍 THỨ 3 (22/09/2026) - NGÀY 15 / 49
A5: STT | B5: Thành Viên | C5: Reel (Link/Ảnh) | D5: Bài Viết 1 (Link/Ảnh) | E5: Bài Viết 2 (Link/Ảnh) | F5: Bài Tập Nhóm (Link/Ảnh) | G5: Chi Tiết Ảnh Minh Chứng | H5: Hoàn Thành | I5: Đánh Giá | J5: Ghi Chú
A6: 1 | B6: Nancy | C6: ='📋 Báo Cáo 49 Ngày'!G131 | D6: ='📋 Báo Cáo 49 Ngày'!I131 | E6: ='📋 Báo Cáo 49 Ngày'!K131 | F6: ='📋 Báo Cáo 49 Ngày'!M131 | G6: =IF(COUNTIF('📋 Báo Cáo 49 Ngày'!H131:N131, "<>")>0, "🖼️ Có kèm ảnh", "—") | H6: ='📋 Báo Cáo 49 Ngày'!O131 | I6: ='📋 Báo Cáo 49 Ngày'!P131
A7: 2 | B7: Hoài Học Mãi | C7: ='📋 Báo Cáo 49 Ngày'!G132 | D7: ='📋 Báo Cáo 49 Ngày'!I132 | E7: ='📋 Báo Cáo 49 Ngày'!K132 | F7: ='📋 Báo Cáo 49 Ngày'!M132 | G7: =IF(COUNTIF('📋 Báo Cáo 49 Ngày'!H132:N132, "<>")>0, "🖼️ Có kèm ảnh", "—") | H7: ='📋 Báo Cáo 49 Ngày'!O132 | I7: ='📋 Báo Cáo 49 Ngày'!P132
A8: 3 | B8: Lambee | C8: ='📋 Báo Cáo 49 Ngày'!G133 | D8: ='📋 Báo Cáo 49 Ngày'!I133 | E8: ='📋 Báo Cáo 49 Ngày'!K133 | F8: ='📋 Báo Cáo 49 Ngày'!M133 | G8: =IF(COUNTIF('📋 Báo Cáo 49 Ngày'!H133:N133, "<>")>0, "🖼️ Có kèm ảnh", "—") | H8: ='📋 Báo Cáo 49 Ngày'!O133 | I8: ='📋 Báo Cáo 49 Ngày'!P133
A9: 4 | B9: Nhung Hoàng | C9: ='📋 Báo Cáo 49 Ngày'!G134 | D9: ='📋 Báo Cáo 49 Ngày'!I134 | E9: ='📋 Báo Cáo 49 Ngày'!K134 | F9: ='📋 Báo Cáo 49 Ngày'!M134 | G9: =IF(COUNTIF('📋 Báo Cáo 49 Ngày'!H134:N134, "<>")>0, "🖼️ Có kèm ảnh", "—") | H9: ='📋 Báo Cáo 49 Ngày'!O134 | I9: ='📋 Báo Cáo 49 Ngày'!P134
A10: 5 | B10: Quỳnh Thu | C10: ='📋 Báo Cáo 49 Ngày'!G135 | D10: ='📋 Báo Cáo 49 Ngày'!I135 | E10: ='📋 Báo Cáo 49 Ngày'!K135 | F10: ='📋 Báo Cáo 49 Ngày'!M135 | G10: =IF(COUNTIF('📋 Báo Cáo 49 Ngày'!H135:N135, "<>")>0, "🖼️ Có kèm ảnh", "—") | H10: ='📋 Báo Cáo 49 Ngày'!O135 | I10: ='📋 Báo Cáo 49 Ngày'!P135
A11: 6 | B11: TanAnh Pham | C11: ='📋 Báo Cáo 49 Ngày'!G136 | D11: ='📋 Báo Cáo 49 Ngày'!I136 | E11: ='📋 Báo Cáo 49 Ngày'!K136 | F11: ='📋 Báo Cáo 49 Ngày'!M136 | G11: =IF(COUNTIF('📋 Báo Cáo 49 Ngày'!H136:N136, "<>")>0, "🖼️ Có kèm ảnh", "—") | H11: ='📋 Báo Cáo 49 Ngày'!O136 | I11: ='📋 Báo Cáo 49 Ngày'!P136
A12: 7 | B12: Thảo Collins Edu | C12: ='📋 Báo Cáo 49 Ngày'!G137 | D12: ='📋 Báo Cáo 49 Ngày'!I137 | E12: ='📋 Báo Cáo 49 Ngày'!K137 | F12: ='📋 Báo Cáo 49 Ngày'!M137 | G12: =IF(COUNTIF('📋 Báo Cáo 49 Ngày'!H137:N137, "<>")>0, "🖼️ Có kèm ảnh", "—") | H12: ='📋 Báo Cáo 49 Ngày'!O137 | I12: ='📋 Báo Cáo 49 Ngày'!P137
A13: 8 | B13: Trần Quế Lam | C13: ='📋 Báo Cáo 49 Ngày'!G138 | D13: ='📋 Báo Cáo 49 Ngày'!I138 | E13: ='📋 Báo Cáo 49 Ngày'!K138 | F13: ='📋 Báo Cáo 49 Ngày'!M138 | G13: =IF(COUNTIF('📋 Báo Cáo 49 Ngày'!H138:N138, "<>")>0, "🖼️ Có kèm ảnh", "—") | H13: ='📋 Báo Cáo 49 Ngày'!O138 | I13: ='📋 Báo Cáo 49 Ngày'!P138
A14: 9 | B14: Phạm Huyền | C14: ='📋 Báo Cáo 49 Ngày'!G139 | D14: ='📋 Báo Cáo 49 Ngày'!I139 | E14: ='📋 Báo Cáo 49 Ngày'!K139 | F14: ='📋 Báo Cáo 49 Ngày'!M139 | G14: =IF(COUNTIF('📋 Báo Cáo 49 Ngày'!H139:N139, "<>")>0, "🖼️ Có kèm ảnh", "—") | H14: ='📋 Báo Cáo 49 Ngày'!O139 | I14: ='📋 Báo Cáo 49 Ngày'!P139
A16: 📍 THỨ 4 (23/09/2026) - NGÀY 16 / 49
A17: STT | B17: Thành Viên | C17: Reel (Link/Ảnh) | D17: Bài Viết 1 (Link/Ảnh) | E17: Bài Viết 2 (Link/Ảnh) | F17: Bài Tập Nhóm (Link/Ảnh) | G17: Chi Tiết Ảnh Minh Chứng | H17: Hoàn Thành | I17: Đánh Giá | J17: Ghi Chú
A18: 1 | B18: Nancy | C18: ='📋 Báo Cáo 49 Ngày'!G140 | D18: ='📋 Báo Cáo 49 Ngày'!I140 | E18: ='📋 Báo Cáo 49 Ngày'!K140 | F18: ='📋 Báo Cáo 49 Ngày'!M140 | G18: =IF(COUNTIF('📋 Báo Cáo 49 Ngày'!H140:N140, "<>")>0, "🖼️ Có kèm ảnh", "—") | H18: ='📋 Báo Cáo 49 Ngày'!O140 | I18: ='📋 Báo Cáo 49 Ngày'!P140
A19: 2 | B19: Hoài Học Mãi | C19: ='📋 Báo Cáo 49 Ngày'!G141 | D19: ='📋 Báo Cáo 49 Ngày'!I141 | E19: ='📋 Báo Cáo 49 Ngày'!K141 | F19: ='📋 Báo Cáo 49 Ngày'!M141 | G19: =IF(COUNTIF('📋 Báo Cáo 49 Ngày'!H141:N141, "<>")>0, "🖼️ Có kèm ảnh", "—") | H19: ='📋 Báo Cáo 49 Ngày'!O141 | I19: ='📋 Báo Cáo 49 Ngày'!P141
A20: 3 | B20: Lambee | C20: ='📋 Báo Cáo 49 Ngày'!G142 | D20: ='📋 Báo Cáo 49 Ngày'!I142 | E20: ='📋 Báo Cáo 49 Ngày'!K142 | F20: ='📋 Báo Cáo 49 Ngày'!M142 | G20: =IF(COUNTIF('📋 Báo Cáo 49 Ngày'!H142:N142, "<>")>0, "🖼️ Có kèm ảnh", "—") | H20: ='📋 Báo Cáo 49 Ngày'!O142 | I20: ='📋 Báo Cáo 49 Ngày'!P142
A21: 4 | B21: Nhung Hoàng | C21: ='📋 Báo Cáo 49 Ngày'!G143 | D21: ='📋 Báo Cáo 49 Ngày'!I143 | E21: ='📋 Báo Cáo 49 Ngày'!K143 | F21: ='📋 Báo Cáo 49 Ngày'!M143 | G21: =IF(COUNTIF('📋 Báo Cáo 49 Ngày'!H143:N143, "<>")>0, "🖼️ Có kèm ảnh", "—") | H21: ='📋 Báo Cáo 49 Ngày'!O143 | I21: ='📋 Báo Cáo 49 Ngày'!P143
A22: 5 | B22: Quỳnh Thu | C22: ='📋 Báo Cáo 49 Ngày'!G144 | D22: ='📋 Báo Cáo 49 Ngày'!I144 | E22: ='📋 Báo Cáo 49 Ngày'!K144 | F22: ='📋 Báo Cáo 49 Ngày'!M144 | G22: =IF(COUNTIF('📋 Báo Cáo 49 Ngày'!H144:N144, "<>")>0, "🖼️ Có kèm ảnh", "—") | H22: ='📋 Báo Cáo 49 Ngày'!O144 | I22: ='📋 Báo Cáo 49 Ngày'!P144
A23: 6 | B23: TanAnh Pham | C23: ='📋 Báo Cáo 49 Ngày'!G145 | D23: ='📋 Báo Cáo 49 Ngày'!I145 | E23: ='📋 Báo Cáo 49 Ngày'!K145 | F23: ='📋 Báo Cáo 49 Ngày'!M145 | G23: =IF(COUNTIF('📋 Báo Cáo 49 Ngày'!H145:N145, "<>")>0, "🖼️ Có kèm ảnh", "—") | H23: ='📋 Báo Cáo 49 Ngày'!O145 | I23: ='📋 Báo Cáo 49 Ngày'!P145
A24: 7 | B24: Thảo Collins Edu | C24: ='📋 Báo Cáo 49 Ngày'!G146 | D24: ='📋 Báo Cáo 49 Ngày'!I146 | E24: ='📋 Báo Cáo 49 Ngày'!K146 | F24: ='📋 Báo Cáo 49 Ngày'!M146 | G24: =IF(COUNTIF('📋 Báo Cáo 49 Ngày'!H146:N146, "<>")>0, "🖼️ Có kèm ảnh", "—") | H24: ='📋 Báo Cáo 49 Ngày'!O146 | I24: ='📋 Báo Cáo 49 Ngày'!P146
A25: 8 | B25: Trần Quế Lam | C25: ='📋 Báo Cáo 49 Ngày'!G147 | D25: ='📋 Báo Cáo 49 Ngày'!I147 | E25: ='📋 Báo Cáo 49 Ngày'!K147 | F25: ='📋 Báo Cáo 49 Ngày'!M147 | G25: =IF(COUNTIF('📋 Báo Cáo 49 Ngày'!H147:N147, "<>")>0, "🖼️ Có kèm ảnh", "—") | H25: ='📋 Báo Cáo 49 Ngày'!O147 | I25: ='📋 Báo Cáo 49 Ngày'!P147
A26: 9 | B26: Phạm Huyền | C26: ='📋 Báo Cáo 49 Ngày'!G148 | D26: ='📋 Báo Cáo 49 Ngày'!I148 | E26: ='📋 Báo Cáo 49 Ngày'!K148 | F26: ='📋 Báo Cáo 49 Ngày'!M148 | G26: =IF(COUNTIF('📋 Báo Cáo 49 Ngày'!H148:N148, "<>")>0, "🖼️ Có kèm ảnh", "—") | H26: ='📋 Báo Cáo 49 Ngày'!O148 | I26: ='📋 Báo Cáo 49 Ngày'!P148
A28: 📍 THỨ 5 (24/09/2026) - NGÀY 17 / 49
A29: STT | B29: Thành Viên | C29: Reel (Link/Ảnh) | D29: Bài Viết 1 (Link/Ảnh) | E29: Bài Viết 2 (Link/Ảnh) | F29: Bài Tập Nhóm (Link/Ảnh) | G29: Chi Tiết Ảnh Minh Chứng | H29: Hoàn Thành | I29: Đánh Giá | J29: Ghi Chú
A30: 1 | B30: Nancy | C30: ='📋 Báo Cáo 49 Ngày'!G149 | D30: ='📋 Báo Cáo 49 Ngày'!I149 | E30: ='📋 Báo Cáo 49 Ngày'!K149 | F30: ='📋 Báo Cáo 49 Ngày'!M149 | G30: =IF(COUNTIF('📋 Báo Cáo 49 Ngày'!H149:N149, "<>")>0, "🖼️ Có kèm ảnh", "—") | H30: ='📋 Báo Cáo 49 Ngày'!O149 | I30: ='📋 Báo Cáo 49 Ngày'!P149
A31: 2 | B31: Hoài Học Mãi | C31: ='📋 Báo Cáo 49 Ngày'!G150 | D31: ='📋 Báo Cáo 49 Ngày'!I150 | E31: ='📋 Báo Cáo 49 Ngày'!K150 | F31: ='📋 Báo Cáo 49 Ngày'!M150 | G31: =IF(COUNTIF('📋 Báo Cáo 49 Ngày'!H150:N150, "<>")>0, "🖼️ Có kèm ảnh", "—") | H31: ='📋 Báo Cáo 49 Ngày'!O150 | I31: ='📋 Báo Cáo 49 Ngày'!P150
A32: 3 | B32: Lambee | C32: ='📋 Báo Cáo 49 Ngày'!G151 | D32: ='📋 Báo Cáo 49 Ngày'!I151 | E32: ='📋 Báo Cáo 49 Ngày'!K151 | F32: ='📋 Báo Cáo 49 Ngày'!M151 | G32: =IF(COUNTIF('📋 Báo Cáo 49 Ngày'!H151:N151, "<>")>0, "🖼️ Có kèm ảnh", "—") | H32: ='📋 Báo Cáo 49 Ngày'!O151 | I32: ='📋 Báo Cáo 49 Ngày'!P151
A33: 4 | B33: Nhung Hoàng | C33: ='📋 Báo Cáo 49 Ngày'!G152 | D33: ='📋 Báo Cáo 49 Ngày'!I152 | E33: ='📋 Báo Cáo 49 Ngày'!K152 | F33: ='📋 Báo Cáo 49 Ngày'!M152 | G33: =IF(COUNTIF('📋 Báo Cáo 49 Ngày'!H152:N152, "<>")>0, "🖼️ Có kèm ảnh", "—") | H33: ='📋 Báo Cáo 49 Ngày'!O152 | I33: ='📋 Báo Cáo 49 Ngày'!P152
A34: 5 | B34: Quỳnh Thu | C34: ='📋 Báo Cáo 49 Ngày'!G153 | D34: ='📋 Báo Cáo 49 Ngày'!I153 | E34: ='📋 Báo Cáo 49 Ngày'!K153 | F34: ='📋 Báo Cáo 49 Ngày'!M153 | G34: =IF(COUNTIF('📋 Báo Cáo 49 Ngày'!H153:N153, "<>")>0, "🖼️ Có kèm ảnh", "—") | H34: ='📋 Báo Cáo 49 Ngày'!O153 | I34: ='📋 Báo Cáo 49 Ngày'!P153
A35: 6 | B35: TanAnh Pham | C35: ='📋 Báo Cáo 49 Ngày'!G154 | D35: ='📋 Báo Cáo 49 Ngày'!I154 | E35: ='📋 Báo Cáo 49 Ngày'!K154 | F35: ='📋 Báo Cáo 49 Ngày'!M154 | G35: =IF(COUNTIF('📋 Báo Cáo 49 Ngày'!H154:N154, "<>")>0, "🖼️ Có kèm ảnh", "—") | H35: ='📋 Báo Cáo 49 Ngày'!O154 | I35: ='📋 Báo Cáo 49 Ngày'!P154
A36: 7 | B36: Thảo Collins Edu | C36: ='📋 Báo Cáo 49 Ngày'!G155 | D36: ='📋 Báo Cáo 49 Ngày'!I155 | E36: ='📋 Báo Cáo 49 Ngày'!K155 | F36: ='📋 Báo Cáo 49 Ngày'!M155 | G36: =IF(COUNTIF('📋 Báo Cáo 49 Ngày'!H155:N155, "<>")>0, "🖼️ Có kèm ảnh", "—") | H36: ='📋 Báo Cáo 49 Ngày'!O155 | I36: ='📋 Báo Cáo 49 Ngày'!P155
A37: 8 | B37: Trần Quế Lam | C37: ='📋 Báo Cáo 49 Ngày'!G156 | D37: ='📋 Báo Cáo 49 Ngày'!I156 | E37: ='📋 Báo Cáo 49 Ngày'!K156 | F37: ='📋 Báo Cáo 49 Ngày'!M156 | G37: =IF(COUNTIF('📋 Báo Cáo 49 Ngày'!H156:N156, "<>")>0, "🖼️ Có kèm ảnh", "—") | H37: ='📋 Báo Cáo 49 Ngày'!O156 | I37: ='📋 Báo Cáo 49 Ngày'!P156
A38: 9 | B38: Phạm Huyền | C38: ='📋 Báo Cáo 49 Ngày'!G157 | D38: ='📋 Báo Cáo 49 Ngày'!I157 | E38: ='📋 Báo Cáo 49 Ngày'!K157 | F38: ='📋 Báo Cáo 49 Ngày'!M157 | G38: =IF(COUNTIF('📋 Báo Cáo 49 Ngày'!H157:N157, "<>")>0, "🖼️ Có kèm ảnh", "—") | H38: ='📋 Báo Cáo 49 Ngày'!O157 | I38: ='📋 Báo Cáo 49 Ngày'!P157
A40: 📍 THỨ 6 (25/09/2026) - NGÀY 18 / 49
A41: STT | B41: Thành Viên | C41: Reel (Link/Ảnh) | D41: Bài Viết 1 (Link/Ảnh) | E41: Bài Viết 2 (Link/Ảnh) | F41: Bài Tập Nhóm (Link/Ảnh) | G41: Chi Tiết Ảnh Minh Chứng | H41: Hoàn Thành | I41: Đánh Giá | J41: Ghi Chú
A42: 1 | B42: Nancy | C42: ='📋 Báo Cáo 49 Ngày'!G158 | D42: ='📋 Báo Cáo 49 Ngày'!I158 | E42: ='📋 Báo Cáo 49 Ngày'!K158 | F42: ='📋 Báo Cáo 49 Ngày'!M158 | G42: =IF(COUNTIF('📋 Báo Cáo 49 Ngày'!H158:N158, "<>")>0, "🖼️ Có kèm ảnh", "—") | H42: ='📋 Báo Cáo 49 Ngày'!O158 | I42: ='📋 Báo Cáo 49 Ngày'!P158
A43: 2 | B43: Hoài Học Mãi | C43: ='📋 Báo Cáo 49 Ngày'!G159 | D43: ='📋 Báo Cáo 49 Ngày'!I159 | E43: ='📋 Báo Cáo 49 Ngày'!K159 | F43: ='📋 Báo Cáo 49 Ngày'!M159 | G43: =IF(COUNTIF('📋 Báo Cáo 49 Ngày'!H159:N159, "<>")>0, "🖼️ Có kèm ảnh", "—") | H43: ='📋 Báo Cáo 49 Ngày'!O159 | I43: ='📋 Báo Cáo 49 Ngày'!P159
A44: 3 | B44: Lambee | C44: ='📋 Báo Cáo 49 Ngày'!G160 | D44: ='📋 Báo Cáo 49 Ngày'!I160 | E44: ='📋 Báo Cáo 49 Ngày'!K160 | F44: ='📋 Báo Cáo 49 Ngày'!M160 | G44: =IF(COUNTIF('📋 Báo Cáo 49 Ngày'!H160:N160, "<>")>0, "🖼️ Có kèm ảnh", "—") | H44: ='📋 Báo Cáo 49 Ngày'!O160 | I44: ='📋 Báo Cáo 49 Ngày'!P160
A45: 4 | B45: Nhung Hoàng | C45: ='📋 Báo Cáo 49 Ngày'!G161 | D45: ='📋 Báo Cáo 49 Ngày'!I161 | E45: ='📋 Báo Cáo 49 Ngày'!K161 | F45: ='📋 Báo Cáo 49 Ngày'!M161 | G45: =IF(COUNTIF('📋 Báo Cáo 49 Ngày'!H161:N161, "<>")>0, "🖼️ Có kèm ảnh", "—") | H45: ='📋 Báo Cáo 49 Ngày'!O161 | I45: ='📋 Báo Cáo 49 Ngày'!P161
...

Sheet Tuần 4
A1: 📅 TUẦN 4 (29/09 - 05/10/2026) - BÁO CÁO 9 THÀNH VIÊN
A4: 📍 THỨ 3 (29/09/2026) - NGÀY 22 / 49
A5: STT | B5: Thành Viên | C5: Reel (Link/Ảnh) | D5: Bài Viết 1 (Link/Ảnh) | E5: Bài Viết 2 (Link/Ảnh) | F5: Bài Tập Nhóm (Link/Ảnh) | G5: Chi Tiết Ảnh Minh Chứng | H5: Hoàn Thành | I5: Đánh Giá | J5: Ghi Chú
A6: 1 | B6: Nancy | C6: ='📋 Báo Cáo 49 Ngày'!G194 | D6: ='📋 Báo Cáo 49 Ngày'!I194 | E6: ='📋 Báo Cáo 49 Ngày'!K194 | F6: ='📋 Báo Cáo 49 Ngày'!M194 | G6: =IF(COUNTIF('📋 Báo Cáo 49 Ngày'!H194:N194, "<>")>0, "🖼️ Có kèm ảnh", "—") | H6: ='📋 Báo Cáo 49 Ngày'!O194 | I6: ='📋 Báo Cáo 49 Ngày'!P194
A7: 2 | B7: Hoài Học Mãi | C7: ='📋 Báo Cáo 49 Ngày'!G195 | D7: ='📋 Báo Cáo 49 Ngày'!I195 | E7: ='📋 Báo Cáo 49 Ngày'!K195 | F7: ='📋 Báo Cáo 49 Ngày'!M195 | G7: =IF(COUNTIF('📋 Báo Cáo 49 Ngày'!H195:N195, "<>")>0, "🖼️ Có kèm ảnh", "—") | H7: ='📋 Báo Cáo 49 Ngày'!O195 | I7: ='📋 Báo Cáo 49 Ngày'!P195
A8: 3 | B8: Lambee | C8: ='📋 Báo Cáo 49 Ngày'!G196 | D8: ='📋 Báo Cáo 49 Ngày'!I196 | E8: ='📋 Báo Cáo 49 Ngày'!K196 | F8: ='📋 Báo Cáo 49 Ngày'!M196 | G8: =IF(COUNTIF('📋 Báo Cáo 49 Ngày'!H196:N196, "<>")>0, "🖼️ Có kèm ảnh", "—") | H8: ='📋 Báo Cáo 49 Ngày'!O196 | I8: ='📋 Báo Cáo 49 Ngày'!P196
A9: 4 | B9: Nhung Hoàng | C9: ='📋 Báo Cáo 49 Ngày'!G197 | D9: ='📋 Báo Cáo 49 Ngày'!I197 | E9: ='📋 Báo Cáo 49 Ngày'!K197 | F9: ='📋 Báo Cáo 49 Ngày'!M197 | G9: =IF(COUNTIF('📋 Báo Cáo 49 Ngày'!H197:N197, "<>")>0, "🖼️ Có kèm ảnh", "—") | H9: ='📋 Báo Cáo 49 Ngày'!O197 | I9: ='📋 Báo Cáo 49 Ngày'!P197
A10: 5 | B10: Quỳnh Thu | C10: ='📋 Báo Cáo 49 Ngày'!G198 | D10: ='📋 Báo Cáo 49 Ngày'!I198 | E10: ='📋 Báo Cáo 49 Ngày'!K198 | F10: ='📋 Báo Cáo 49 Ngày'!M198 | G10: =IF(COUNTIF('📋 Báo Cáo 49 Ngày'!H198:N198, "<>")>0, "🖼️ Có kèm ảnh", "—") | H10: ='📋 Báo Cáo 49 Ngày'!O198 | I10: ='📋 Báo Cáo 49 Ngày'!P198
A11: 6 | B11: TanAnh Pham | C11: ='📋 Báo Cáo 49 Ngày'!G199 | D11: ='📋 Báo Cáo 49 Ngày'!I199 | E11: ='📋 Báo Cáo 49 Ngày'!K199 | F11: ='📋 Báo Cáo 49 Ngày'!M199 | G11: =IF(COUNTIF('📋 Báo Cáo 49 Ngày'!H199:N199, "<>")>0, "🖼️ Có kèm ảnh", "—") | H11: ='📋 Báo Cáo 49 Ngày'!O199 | I11: ='📋 Báo Cáo 49 Ngày'!P199
A12: 7 | B12: Thảo Collins Edu | C12: ='📋 Báo Cáo 49 Ngày'!G200 | D12: ='📋 Báo Cáo 49 Ngày'!I200 | E12: ='📋 Báo Cáo 49 Ngày'!K200 | F12: ='📋 Báo Cáo 49 Ngày'!M200 | G12: =IF(COUNTIF('📋 Báo Cáo 49 Ngày'!H200:N200, "<>")>0, "🖼️ Có kèm ảnh", "—") | H12: ='📋 Báo Cáo 49 Ngày'!O200 | I12: ='📋 Báo Cáo 49 Ngày'!P200
A13: 8 | B13: Trần Quế Lam | C13: ='📋 Báo Cáo 49 Ngày'!G201 | D13: ='📋 Báo Cáo 49 Ngày'!I201 | E13: ='📋 Báo Cáo 49 Ngày'!K201 | F13: ='📋 Báo Cáo 49 Ngày'!M201 | G13: =IF(COUNTIF('📋 Báo Cáo 49 Ngày'!H201:N201, "<>")>0, "🖼️ Có kèm ảnh", "—") | H13: ='📋 Báo Cáo 49 Ngày'!O201 | I13: ='📋 Báo Cáo 49 Ngày'!P201
A14: 9 | B14: Phạm Huyền | C14: ='📋 Báo Cáo 49 Ngày'!G202 | D14: ='📋 Báo Cáo 49 Ngày'!I202 | E14: ='📋 Báo Cáo 49 Ngày'!K202 | F14: ='📋 Báo Cáo 49 Ngày'!M202 | G14: =IF(COUNTIF('📋 Báo Cáo 49 Ngày'!H202:N202, "<>")>0, "🖼️ Có kèm ảnh", "—") | H14: ='📋 Báo Cáo 49 Ngày'!O202 | I14: ='📋 Báo Cáo 49 Ngày'!P202
A16: 📍 THỨ 4 (30/09/2026) - NGÀY 23 / 49
A17: STT | B17: Thành Viên | C17: Reel (Link/Ảnh) | D17: Bài Viết 1 (Link/Ảnh) | E17: Bài Viết 2 (Link/Ảnh) | F17: Bài Tập Nhóm (Link/Ảnh) | G17: Chi Tiết Ảnh Minh Chứng | H17: Hoàn Thành | I17: Đánh Giá | J17: Ghi Chú
A18: 1 | B18: Nancy | C18: ='📋 Báo Cáo 49 Ngày'!G203 | D18: ='📋 Báo Cáo 49 Ngày'!I203 | E18: ='📋 Báo Cáo 49 Ngày'!K203 | F18: ='📋 Báo Cáo 49 Ngày'!M203 | G18: =IF(COUNTIF('📋 Báo Cáo 49 Ngày'!H203:N203, "<>")>0, "🖼️ Có kèm ảnh", "—") | H18: ='📋 Báo Cáo 49 Ngày'!O203 | I18: ='📋 Báo Cáo 49 Ngày'!P203
A19: 2 | B19: Hoài Học Mãi | C19: ='📋 Báo Cáo 49 Ngày'!G204 | D19: ='📋 Báo Cáo 49 Ngày'!I204 | E19: ='📋 Báo Cáo 49 Ngày'!K204 | F19: ='📋 Báo Cáo 49 Ngày'!M204 | G19: =IF(COUNTIF('📋 Báo Cáo 49 Ngày'!H204:N204, "<>")>0, "🖼️ Có kèm ảnh", "—") | H19: ='📋 Báo Cáo 49 Ngày'!O204 | I19: ='📋 Báo Cáo 49 Ngày'!P204
A20: 3 | B20: Lambee | C20: ='📋 Báo Cáo 49 Ngày'!G205 | D20: ='📋 Báo Cáo 49 Ngày'!I205 | E20: ='📋 Báo Cáo 49 Ngày'!K205 | F20: ='📋 Báo Cáo 49 Ngày'!M205 | G20: =IF(COUNTIF('📋 Báo Cáo 49 Ngày'!H205:N205, "<>")>0, "🖼️ Có kèm ảnh", "—") | H20: ='📋 Báo Cáo 49 Ngày'!O205 | I20: ='📋 Báo Cáo 49 Ngày'!P205
A21: 4 | B21: Nhung Hoàng | C21: ='📋 Báo Cáo 49 Ngày'!G206 | D21: ='📋 Báo Cáo 49 Ngày'!I206 | E21: ='📋 Báo Cáo 49 Ngày'!K206 | F21: ='📋 Báo Cáo 49 Ngày'!M206 | G21: =IF(COUNTIF('📋 Báo Cáo 49 Ngày'!H206:N206, "<>")>0, "🖼️ Có kèm ảnh", "—") | H21: ='📋 Báo Cáo 49 Ngày'!O206 | I21: ='📋 Báo Cáo 49 Ngày'!P206
A22: 5 | B22: Quỳnh Thu | C22: ='📋 Báo Cáo 49 Ngày'!G207 | D22: ='📋 Báo Cáo 49 Ngày'!I207 | E22: ='📋 Báo Cáo 49 Ngày'!K207 | F22: ='📋 Báo Cáo 49 Ngày'!M207 | G22: =IF(COUNTIF('📋 Báo Cáo 49 Ngày'!H207:N207, "<>")>0, "🖼️ Có kèm ảnh", "—") | H22: ='📋 Báo Cáo 49 Ngày'!O207 | I22: ='📋 Báo Cáo 49 Ngày'!P207
A23: 6 | B23: TanAnh Pham | C23: ='📋 Báo Cáo 49 Ngày'!G208 | D23: ='📋 Báo Cáo 49 Ngày'!I208 | E23: ='📋 Báo Cáo 49 Ngày'!K208 | F23: ='📋 Báo Cáo 49 Ngày'!M208 | G23: =IF(COUNTIF('📋 Báo Cáo 49 Ngày'!H208:N208, "<>")>0, "🖼️ Có kèm ảnh", "—") | H23: ='📋 Báo Cáo 49 Ngày'!O208 | I23: ='📋 Báo Cáo 49 Ngày'!P208
A24: 7 | B24: Thảo Collins Edu | C24: ='📋 Báo Cáo 49 Ngày'!G209 | D24: ='📋 Báo Cáo 49 Ngày'!I209 | E24: ='📋 Báo Cáo 49 Ngày'!K209 | F24: ='📋 Báo Cáo 49 Ngày'!M209 | G24: =IF(COUNTIF('📋 Báo Cáo 49 Ngày'!H209:N209, "<>")>0, "🖼️ Có kèm ảnh", "—") | H24: ='📋 Báo Cáo 49 Ngày'!O209 | I24: ='📋 Báo Cáo 49 Ngày'!P209
A25: 8 | B25: Trần Quế Lam | C25: ='📋 Báo Cáo 49 Ngày'!G210 | D25: ='📋 Báo Cáo 49 Ngày'!I210 | E25: ='📋 Báo Cáo 49 Ngày'!K210 | F25: ='📋 Báo Cáo 49 Ngày'!M210 | G25: =IF(COUNTIF('📋 Báo Cáo 49 Ngày'!H210:N210, "<>")>0, "🖼️ Có kèm ảnh", "—") | H25: ='📋 Báo Cáo 49 Ngày'!O210 | I25: ='📋 Báo Cáo 49 Ngày'!P210
A26: 9 | B26: Phạm Huyền | C26: ='📋 Báo Cáo 49 Ngày'!G211 | D26: ='📋 Báo Cáo 49 Ngày'!I211 | E26: ='📋 Báo Cáo 49 Ngày'!K211 | F26: ='📋 Báo Cáo 49 Ngày'!M211 | G26: =IF(COUNTIF('📋 Báo Cáo 49 Ngày'!H211:N211, "<>")>0, "🖼️ Có kèm ảnh", "—") | H26: ='📋 Báo Cáo 49 Ngày'!O211 | I26: ='📋 Báo Cáo 49 Ngày'!P211
A28: 📍 THỨ 5 (01/10/2026) - NGÀY 24 / 49
A29: STT | B29: Thành Viên | C29: Reel (Link/Ảnh) | D29: Bài Viết 1 (Link/Ảnh) | E29: Bài Viết 2 (Link/Ảnh) | F29: Bài Tập Nhóm (Link/Ảnh) | G29: Chi Tiết Ảnh Minh Chứng | H29: Hoàn Thành | I29: Đánh Giá | J29: Ghi Chú
A30: 1 | B30: Nancy | C30: ='📋 Báo Cáo 49 Ngày'!G212 | D30: ='📋 Báo Cáo 49 Ngày'!I212 | E30: ='📋 Báo Cáo 49 Ngày'!K212 | F30: ='📋 Báo Cáo 49 Ngày'!M212 | G30: =IF(COUNTIF('📋 Báo Cáo 49 Ngày'!H212:N212, "<>")>0, "🖼️ Có kèm ảnh", "—") | H30: ='📋 Báo Cáo 49 Ngày'!O212 | I30: ='📋 Báo Cáo 49 Ngày'!P212
A31: 2 | B31: Hoài Học Mãi | C31: ='📋 Báo Cáo 49 Ngày'!G213 | D31: ='📋 Báo Cáo 49 Ngày'!I213 | E31: ='📋 Báo Cáo 49 Ngày'!K213 | F31: ='📋 Báo Cáo 49 Ngày'!M213 | G31: =IF(COUNTIF('📋 Báo Cáo 49 Ngày'!H213:N213, "<>")>0, "🖼️ Có kèm ảnh", "—") | H31: ='📋 Báo Cáo 49 Ngày'!O213 | I31: ='📋 Báo Cáo 49 Ngày'!P213
A32: 3 | B32: Lambee | C32: ='📋 Báo Cáo 49 Ngày'!G214 | D32: ='📋 Báo Cáo 49 Ngày'!I214 | E32: ='📋 Báo Cáo 49 Ngày'!K214 | F32: ='📋 Báo Cáo 49 Ngày'!M214 | G32: =IF(COUNTIF('📋 Báo Cáo 49 Ngày'!H214:N214, "<>")>0, "🖼️ Có kèm ảnh", "—") | H32: ='📋 Báo Cáo 49 Ngày'!O214 | I32: ='📋 Báo Cáo 49 Ngày'!P214
A33: 4 | B33: Nhung Hoàng | C33: ='📋 Báo Cáo 49 Ngày'!G215 | D33: ='📋 Báo Cáo 49 Ngày'!I215 | E33: ='📋 Báo Cáo 49 Ngày'!K215 | F33: ='📋 Báo Cáo 49 Ngày'!M215 | G33: =IF(COUNTIF('📋 Báo Cáo 49 Ngày'!H215:N215, "<>")>0, "🖼️ Có kèm ảnh", "—") | H33: ='📋 Báo Cáo 49 Ngày'!O215 | I33: ='📋 Báo Cáo 49 Ngày'!P215
A34: 5 | B34: Quỳnh Thu | C34: ='📋 Báo Cáo 49 Ngày'!G216 | D34: ='📋 Báo Cáo 49 Ngày'!I216 | E34: ='📋 Báo Cáo 49 Ngày'!K216 | F34: ='📋 Báo Cáo 49 Ngày'!M216 | G34: =IF(COUNTIF('📋 Báo Cáo 49 Ngày'!H216:N216, "<>")>0, "🖼️ Có kèm ảnh", "—") | H34: ='📋 Báo Cáo 49 Ngày'!O216 | I34: ='📋 Báo Cáo 49 Ngày'!P216
A35: 6 | B35: TanAnh Pham | C35: ='📋 Báo Cáo 49 Ngày'!G217 | D35: ='📋 Báo Cáo 49 Ngày'!I217 | E35: ='📋 Báo Cáo 49 Ngày'!K217 | F35: ='📋 Báo Cáo 49 Ngày'!M217 | G35: =IF(COUNTIF('📋 Báo Cáo 49 Ngày'!H217:N217, "<>")>0, "🖼️ Có kèm ảnh", "—") | H35: ='📋 Báo Cáo 49 Ngày'!O217 | I35: ='📋 Báo Cáo 49 Ngày'!P217
A36: 7 | B36: Thảo Collins Edu | C36: ='📋 Báo Cáo 49 Ngày'!G218 | D36: ='📋 Báo Cáo 49 Ngày'!I218 | E36: ='📋 Báo Cáo 49 Ngày'!K218 | F36: ='📋 Báo Cáo 49 Ngày'!M218 | G36: =IF(COUNTIF('📋 Báo Cáo 49 Ngày'!H218:N218, "<>")>0, "🖼️ Có kèm ảnh", "—") | H36: ='📋 Báo Cáo 49 Ngày'!O218 | I36: ='📋 Báo Cáo 49 Ngày'!P218
A37: 8 | B37: Trần Quế Lam | C37: ='📋 Báo Cáo 49 Ngày'!G219 | D37: ='📋 Báo Cáo 49 Ngày'!I219 | E37: ='📋 Báo Cáo 49 Ngày'!K219 | F37: ='📋 Báo Cáo 49 Ngày'!M219 | G37: =IF(COUNTIF('📋 Báo Cáo 49 Ngày'!H219:N219, "<>")>0, "🖼️ Có kèm ảnh", "—") | H37: ='📋 Báo Cáo 49 Ngày'!O219 | I37: ='📋 Báo Cáo 49 Ngày'!P219
A38: 9 | B38: Phạm Huyền | C38: ='📋 Báo Cáo 49 Ngày'!G220 | D38: ='📋 Báo Cáo 49 Ngày'!I220 | E38: ='📋 Báo Cáo 49 Ngày'!K220 | F38: ='📋 Báo Cáo 49 Ngày'!M220 | G38: =IF(COUNTIF('📋 Báo Cáo 49 Ngày'!H220:N220, "<>")>0, "🖼️ Có kèm ảnh", "—") | H38: ='📋 Báo Cáo 49 Ngày'!O220 | I38: ='📋 Báo Cáo 49 Ngày'!P220
A40: 📍 THỨ 6 (02/10/2026) - NGÀY 25 / 49
A41: STT | B41: Thành Viên | C41: Reel (Link/Ảnh) | D41: Bài Viết 1 (Link/Ảnh) | E41: Bài Viết 2 (Link/Ảnh) | F41: Bài Tập Nhóm (Link/Ảnh) | G41: Chi Tiết Ảnh Minh Chứng | H41: Hoàn Thành | I41: Đánh Giá | J41: Ghi Chú
A42: 1 | B42: Nancy | C42: ='📋 Báo Cáo 49 Ngày'!G221 | D42: ='📋 Báo Cáo 49 Ngày'!I221 | E42: ='📋 Báo Cáo 49 Ngày'!K221 | F42: ='📋 Báo Cáo 49 Ngày'!M221 | G42: =IF(COUNTIF('📋 Báo Cáo 49 Ngày'!H221:N221, "<>")>0, "🖼️ Có kèm ảnh", "—") | H42: ='📋 Báo Cáo 49 Ngày'!O221 | I42: ='📋 Báo Cáo 49 Ngày'!P221
A43: 2 | B43: Hoài Học Mãi | C43: ='📋 Báo Cáo 49 Ngày'!G222 | D43: ='📋 Báo Cáo 49 Ngày'!I222 | E43: ='📋 Báo Cáo 49 Ngày'!K222 | F43: ='📋 Báo Cáo 49 Ngày'!M222 | G43: =IF(COUNTIF('📋 Báo Cáo 49 Ngày'!H222:N222, "<>")>0, "🖼️ Có kèm ảnh", "—") | H43: ='📋 Báo Cáo 49 Ngày'!O222 | I43: ='📋 Báo Cáo 49 Ngày'!P222
A44: 3 | B44: Lambee | C44: ='📋 Báo Cáo 49 Ngày'!G223 | D44: ='📋 Báo Cáo 49 Ngày'!I223 | E44: ='📋 Báo Cáo 49 Ngày'!K223 | F44: ='📋 Báo Cáo 49 Ngày'!M223 | G44: =IF(COUNTIF('📋 Báo Cáo 49 Ngày'!H223:N223, "<>")>0, "🖼️ Có kèm ảnh", "—") | H44: ='📋 Báo Cáo 49 Ngày'!O223 | I44: ='📋 Báo Cáo 49 Ngày'!P223
A45: 4 | B45: Nhung Hoàng | C45: ='📋 Báo Cáo 49 Ngày'!G224 | D45: ='📋 Báo Cáo 49 Ngày'!I224 | E45: ='📋 Báo Cáo 49 Ngày'!K224 | F45: ='📋 Báo Cáo 49 Ngày'!M224 | G45: =IF(COUNTIF('📋 Báo Cáo 49 Ngày'!H224:N224, "<>")>0, "🖼️ Có kèm ảnh", "—") | H45: ='📋 Báo Cáo 49 Ngày'!O224 | I45: ='📋 Báo Cáo 49 Ngày'!P224
...

Sheet Tuần 5
A1: 📅 TUẦN 5 (06/10 - 12/10/2026) - BÁO CÁO 9 THÀNH VIÊN
A4: 📍 THỨ 3 (06/10/2026) - NGÀY 29 / 49
A5: STT | B5: Thành Viên | C5: Reel (Link/Ảnh) | D5: Bài Viết 1 (Link/Ảnh) | E5: Bài Viết 2 (Link/Ảnh) | F5: Bài Tập Nhóm (Link/Ảnh) | G5: Chi Tiết Ảnh Minh Chứng | H5: Hoàn Thành | I5: Đánh Giá | J5: Ghi Chú
A6: 1 | B6: Nancy | C6: ='📋 Báo Cáo 49 Ngày'!G257 | D6: ='📋 Báo Cáo 49 Ngày'!I257 | E6: ='📋 Báo Cáo 49 Ngày'!K257 | F6: ='📋 Báo Cáo 49 Ngày'!M257 | G6: =IF(COUNTIF('📋 Báo Cáo 49 Ngày'!H257:N257, "<>")>0, "🖼️ Có kèm ảnh", "—") | H6: ='📋 Báo Cáo 49 Ngày'!O257 | I6: ='📋 Báo Cáo 49 Ngày'!P257
A7: 2 | B7: Hoài Học Mãi | C7: ='📋 Báo Cáo 49 Ngày'!G258 | D7: ='📋 Báo Cáo 49 Ngày'!I258 | E7: ='📋 Báo Cáo 49 Ngày'!K258 | F7: ='📋 Báo Cáo 49 Ngày'!M258 | G7: =IF(COUNTIF('📋 Báo Cáo 49 Ngày'!H258:N258, "<>")>0, "🖼️ Có kèm ảnh", "—") | H7: ='📋 Báo Cáo 49 Ngày'!O258 | I7: ='📋 Báo Cáo 49 Ngày'!P258
A8: 3 | B8: Lambee | C8: ='📋 Báo Cáo 49 Ngày'!G259 | D8: ='📋 Báo Cáo 49 Ngày'!I259 | E8: ='📋 Báo Cáo 49 Ngày'!K259 | F8: ='📋 Báo Cáo 49 Ngày'!M259 | G8: =IF(COUNTIF('📋 Báo Cáo 49 Ngày'!H259:N259, "<>")>0, "🖼️ Có kèm ảnh", "—") | H8: ='📋 Báo Cáo 49 Ngày'!O259 | I8: ='📋 Báo Cáo 49 Ngày'!P259
A9: 4 | B9: Nhung Hoàng | C9: ='📋 Báo Cáo 49 Ngày'!G260 | D9: ='📋 Báo Cáo 49 Ngày'!I260 | E9: ='📋 Báo Cáo 49 Ngày'!K260 | F9: ='📋 Báo Cáo 49 Ngày'!M260 | G9: =IF(COUNTIF('📋 Báo Cáo 49 Ngày'!H260:N260, "<>")>0, "🖼️ Có kèm ảnh", "—") | H9: ='📋 Báo Cáo 49 Ngày'!O260 | I9: ='📋 Báo Cáo 49 Ngày'!P260
A10: 5 | B10: Quỳnh Thu | C10: ='📋 Báo Cáo 49 Ngày'!G261 | D10: ='📋 Báo Cáo 49 Ngày'!I261 | E10: ='📋 Báo Cáo 49 Ngày'!K261 | F10: ='📋 Báo Cáo 49 Ngày'!M261 | G10: =IF(COUNTIF('📋 Báo Cáo 49 Ngày'!H261:N261, "<>")>0, "🖼️ Có kèm ảnh", "—") | H10: ='📋 Báo Cáo 49 Ngày'!O261 | I10: ='📋 Báo Cáo 49 Ngày'!P261
A11: 6 | B11: TanAnh Pham | C11: ='📋 Báo Cáo 49 Ngày'!G262 | D11: ='📋 Báo Cáo 49 Ngày'!I262 | E11: ='📋 Báo Cáo 49 Ngày'!K262 | F11: ='📋 Báo Cáo 49 Ngày'!M262 | G11: =IF(COUNTIF('📋 Báo Cáo 49 Ngày'!H262:N262, "<>")>0, "🖼️ Có kèm ảnh", "—") | H11: ='📋 Báo Cáo 49 Ngày'!O262 | I11: ='📋 Báo Cáo 49 Ngày'!P262
A12: 7 | B12: Thảo Collins Edu | C12: ='📋 Báo Cáo 49 Ngày'!G263 | D12: ='📋 Báo Cáo 49 Ngày'!I263 | E12: ='📋 Báo Cáo 49 Ngày'!K263 | F12: ='📋 Báo Cáo 49 Ngày'!M263 | G12: =IF(COUNTIF('📋 Báo Cáo 49 Ngày'!H263:N263, "<>")>0, "🖼️ Có kèm ảnh", "—") | H12: ='📋 Báo Cáo 49 Ngày'!O263 | I12: ='📋 Báo Cáo 49 Ngày'!P263
A13: 8 | B13: Trần Quế Lam | C13: ='📋 Báo Cáo 49 Ngày'!G264 | D13: ='📋 Báo Cáo 49 Ngày'!I264 | E13: ='📋 Báo Cáo 49 Ngày'!K264 | F13: ='📋 Báo Cáo 49 Ngày'!M264 | G13: =IF(COUNTIF('📋 Báo Cáo 49 Ngày'!H264:N264, "<>")>0, "🖼️ Có kèm ảnh", "—") | H13: ='📋 Báo Cáo 49 Ngày'!O264 | I13: ='📋 Báo Cáo 49 Ngày'!P264
A14: 9 | B14: Phạm Huyền | C14: ='📋 Báo Cáo 49 Ngày'!G265 | D14: ='📋 Báo Cáo 49 Ngày'!I265 | E14: ='📋 Báo Cáo 49 Ngày'!K265 | F14: ='📋 Báo Cáo 49 Ngày'!M265 | G14: =IF(COUNTIF('📋 Báo Cáo 49 Ngày'!H265:N265, "<>")>0, "🖼️ Có kèm ảnh", "—") | H14: ='📋 Báo Cáo 49 Ngày'!O265 | I14: ='📋 Báo Cáo 49 Ngày'!P265
A16: 📍 THỨ 4 (07/10/2026) - NGÀY 30 / 49
A17: STT | B17: Thành Viên | C17: Reel (Link/Ảnh) | D17: Bài Viết 1 (Link/Ảnh) | E17: Bài Viết 2 (Link/Ảnh) | F17: Bài Tập Nhóm (Link/Ảnh) | G17: Chi Tiết Ảnh Minh Chứng | H17: Hoàn Thành | I17: Đánh Giá | J17: Ghi Chú
